Workbook
Name Slicer_Month: #N/A
Name Slicer_Year: #N/A
Name start_day: #REF!

Sheet General Calendar
C3: This calendar show only Deadlines for every Finance Team commitment. Each team should organize their workstreams to present reviewed & final deliverables and fulfill each task on the deadline date.
C4: For more detail use the following schedule: | E4: Detailed Tasks
K5: ▪ | L5: Click on Month list (G7) to view one team member only
C6: Finance Team Commitments | G6: Month | H6: Year | I6: Main Owner / Entire Team | K6: ▪ | L6: Click on Year list (H7) to view one team member only
G7: July | H7: 2025 | I7: Finance Manager | K7: ▪ | L7: Click on Main Owner list (I7) to view one team member only
K8: ▪ | L8: Click on Detailed Task (E4) to view team members involved
C9: Sunday | D9: Monday | E9: Tuesday | F9: Wednesday | G9: Thursday | H9: Friday | I9: Saturday
C10: =_xlfn.IFNA(_xlfn.XLOOKUP(C11,'Date master'!$E:$E,'Date master'!$I:$I),"") | D10: =_xlfn.IFNA(_xlfn.XLOOKUP(D11,'Date master'!$E:$E,'Date master'!$I:$I),"") | E10: =_xlfn.IFNA(_xlfn.XLOOKUP(E11,'Date master'!$E:$E,'Date master'!$I:$I),"") -> 1 | F10: =_xlfn.IFNA(_xlfn.XLOOKUP(F11,'Date master'!$E:$E,'Date master'!$I:$I),"") -> 2 | G10: =_xlfn.IFNA(_xlfn.XLOOKUP(G11,'Date master'!$E:$E,'Date master'!$I:$I),"") -> 3 | H10: =_xlfn.IFNA(_xlfn.XLOOKUP(H11,'Date master'!$E:$E,'Date master'!$I:$I),"") | I10: =_xlfn.IFNA(_xlfn.XLOOKUP(I11,'Date master'!$E:$E,'Date master'!$I:$I),"")
C11: =DATEVALUE(1&$G$7&$H$7)-WEEKDAY(DATEVALUE(1&$G$7&$H$7),2) -> 45837 | D11: =C11+1 -> 45838 | E11: =D11+1 -> 45839 | F11: =E11+1 -> 45840 | G11: =F11+1 -> 45841 | H11: =G11+1 -> 45842 | I11: =H11+1 -> 45843
C12: {=IFERROR( _xlfn.TEXTJOIN(CHAR(10), TRUE, _xlfn._xlws.FILTER( "- " & 'Commitments & Ownership Matrix'!$B$5:$B$30, ( ( ($I$7="Entire Team") * ('Commitments & Ownership Matrix'!$D$5:$D$30=C10) + (('Commitments & Ownership Matrix'!$F$5:$F$30=$I$7) * ('Commitments & Ownership Matrix'!$D$5:$D$30=C10)) ) * ('Commitments & Ownership Matrix'!$B$5:$B$30 <> "") ) ) ), "" )} | D12: {=IFERROR( _xlfn.TEXTJOIN(CHAR(10), TRUE, _xlfn._xlws.FILTER( "- " & 'Commitments & Ownership Matrix'!$B$5:$B$30, ( ( ($I$7="Entire Team") * ('Commitments & Ownership Matrix'!$D$5:$D$30=D10) + (('Commitments & Ownership Matrix'!$F$5:$F$30=$I$7) * ('Commitments & Ownership Matrix'!$D$5:$D$30=D10)) ) * ('Commitments & Ownership Matrix'!$B$5:$B$30 <> "") ) ) ), "" )} | E12: {=IFERROR( _xlfn.TEXTJOIN(CHAR(10), TRUE, _xlfn._xlws.FILTER( "- " & 'Commitments & Ownership Matrix'!$B$5:$B$30, ( ( ($I$7="Entire Team") * ('Commitments & Ownership Matrix'!$D$5:$D$30=E10) + (('Commitments & Ownership Matrix'!$F$5:$F$30=$I$7) * ('Commitments & Ownership Matrix'!$D$5:$D$30=E10)) ) * ('Commitments & Ownership Matrix'!$B$5:$B$30 <> "") ) ) ), "" )} | F12: {=IFERROR( _xlfn.TEXTJOIN(CHAR(10), TRUE, _xlfn._xlws.FILTER( "- " & 'Commitments & Ownership Matrix'!$B$5:$B$30, ( ( ($I$7="Entire Team") * ('Commitments & Ownership Matrix'!$D$5:$D$30=F10) + (('Commitments & Ownership Matrix'!$F$5:$F$30=$I$7) * ('Commitments & Ownership Matrix'!$D$5:$D$30=F10)) ) * ('Commitments & Ownership Matrix'!$B$5:$B$30 <> "") ) ) ), "" )} | G12: {=IFERROR( _xlfn.TEXTJOIN(CHAR(10), TRUE, _xlfn._xlws.FILTER( "- " & 'Commitments & Ownership Matrix'!$B$5:$B$30, ( ( ($I$7="Entire Team") * ('Commitments & Ownership Matrix'!$D$5:$D$30=G10) + (('Commitments & Ownership Matrix'!$F$5:$F$30=$I$7) * ('Commitments & Ownership Matrix'!$D$5:$D$30=G10)) ) * ('Commitments & Ownership Matrix'!$B$5:$B$30 <> "") ) ) ), "" )} | H12: {=IFERROR( _xlfn.TEXTJOIN(CHAR(10), TRUE, _xlfn._xlws.FILTER( "- " & 'Commitments & Ownership Matrix'!$B$5:$B$30, ( ( ($I$7="Entire Team") * ('Commitments & Ownership Matrix'!$D$5:$D$30=H10) + (('Commitments & Ownership Matrix'!$F$5:$F$30=$I$7) * ('Commitments & Ownership Matrix'!$D$5:$D$30=H10)) ) * ('Commitments & Ownership Matrix'!$B$5:$B$30 <> "") ) ) ), "" )} | I12: {=IFERROR( _xlfn.TEXTJOIN(CHAR(10), TRUE, _xlfn._xlws.FILTER( "- " & 'Commitments & Ownership Matrix'!$B$5:$B$30, ( ( ($I$7="Entire Team") * ('Commitments & Ownership Matrix'!$D$5:$D$30=I10) + (('Commitments & Ownership Matrix'!$F$5:$F$30=$I$7) * ('Commitments & Ownership Matrix'!$D$5:$D$30=I10)) ) * ('Commitments & Ownership Matrix'!$B$5:$B$30 <> "") ) ) ), "" )}
C13: {=IFERROR( _xlfn.TEXTJOIN(CHAR(10), TRUE, _xlfn._xlws.FILTER( "- " & 'Commitments & Ownership Matrix'!$B$5:$B$40, ( (($I$7="Entire Team") * ('Commitments & Ownership Matrix'!$E$5:$E$40=C11)) + (('Commitments & Ownership Matrix'!$F$5:$F$40=$I$7) * ('Commitments & Ownership Matrix'!$E$5:$E$40=C11)) ) * ('Commitments & Ownership Matrix'!$H$5:$H$40="Exceptional") * ('Commitments & Ownership Matrix'!$B$5:$B$40<>"") ) ), "" )} | D13: {=IFERROR( _xlfn.TEXTJOIN(CHAR(10), TRUE, _xlfn._xlws.FILTER( "- " & 'Commitments & Ownership Matrix'!$B$5:$B$40, ( (($I$7="Entire Team") * ('Commitments & Ownership Matrix'!$E$5:$E$40=D11)) + (('Commitments & Ownership Matrix'!$F$5:$F$40=$I$7) * ('Commitments & Ownership Matrix'!$E$5:$E$40=D11)) ) * ('Commitments & Ownership Matrix'!$H$5:$H$40="Exceptional") * ('Commitments & Ownership Matrix'!$B$5:$B$40<>"") ) ), "" )} | E13: {=IFERROR( _xlfn.TEXTJOIN(CHAR(10), TRUE, _xlfn._xlws.FILTER( "- " & 'Commitments & Ownership Matrix'!$B$5:$B$40, ( (($I$7="Entire Team") * ('Commitments & Ownership Matrix'!$E$5:$E$40=E11)) + (('Commitments & Ownership Matrix'!$F$5:$F$40=$I$7) * ('Commitments & Ownership Matrix'!$E$5:$E$40=E11)) ) * ('Commitments & Ownership Matrix'!$H$5:$H$40="Exceptional") * ('Commitments & Ownership Matrix'!$B$5:$B$40<>"") ) ), "" )} | F13: {=IFERROR( _xlfn.TEXTJOIN(CHAR(10), TRUE, _xlfn._xlws.FILTER( "- " & 'Commitments & Ownership Matrix'!$B$5:$B$40, ( (($I$7="Entire Team") * ('Commitments & Ownership Matrix'!$E$5:$E$40=F11)) + (('Commitments & Ownership Matrix'!$F$5:$F$40=$I$7) * ('Commitments & Ownership Matrix'!$E$5:$E$40=F11)) ) * ('Commitments & Ownership Matrix'!$H$5:$H$40="Exceptional") * ('Commitments & Ownership Matrix'!$B$5:$B$40<>"") ) ), "" )} | G13: {=IFERROR( _xlfn.TEXTJOIN(CHAR(10), TRUE, _xlfn._xlws.FILTER( "- " & 'Commitments & Ownership Matrix'!$B$5:$B$40, ( (($I$7="Entire Team") * ('Commitments & Ownership Matrix'!$E$5:$E$40=G11)) + (('Commitments & Ownership Matrix'!$F$5:$F$40=$I$7) * ('Commitments & Ownership Matrix'!$E$5:$E$40=G11)) ) * ('Commitments & Ownership Matrix'!$H$5:$H$40="Exceptional") * ('Commitments & Ownership Matrix'!$B$5:$B$40<>"") ) ), "" )} | H13: {=IFERROR( _xlfn.TEXTJOIN(CHAR(10), TRUE, _xlfn._xlws.FILTER( "- " & 'Commitments & Ownership Matrix'!$B$5:$B$40, ( (($I$7="Entire Team") * ('Commitments & Ownership Matrix'!$E$5:$E$40=H11)) + (('Commitments & Ownership Matrix'!$F$5:$F$40=$I$7) * ('Commitments & Ownership Matrix'!$E$5:$E$40=H11)) ) * ('Commitments & Ownership Matrix'!$H$5:$H$40="Exceptional") * ('Commitments & Ownership Matrix'!$B$5:$B$40<>"") ) ), "" )} | I13: {=IFERROR( _xlfn.TEXTJOIN(CHAR(10), TRUE, _xlfn._xlws.FILTER( "- " & 'Commitments & Ownership Matrix'!$B$5:$B$40, ( (($I$7="Entire Team") * ('Commitments & Ownership Matrix'!$E$5:$E$40=I11)) + (('Commitments & Ownership Matrix'!$F$5:$F$40=$I$7) * ('Commitments & Ownership Matrix'!$E$5:$E$40=I11)) ) * ('Commitments & Ownership Matrix'!$H$5:$H$40="Exceptional") * ('Commitments & Ownership Matrix'!$B$5:$B$40<>"") ) ), "" )}
D14: =_xlfn.XLOOKUP(D11, 'Date master'!$E:$E,'Date master'!$F:$F, "") & " " & _xlfn.XLOOKUP(D11, 'Date master'!$E:$E, 'Date master'!$G:$G, "") | E14: =_xlfn.XLOOKUP(E11, 'Date master'!$E:$E,'Date master'!$F:$F, "") & " " & _xlfn.XLOOKUP(E11, 'Date master'!$E:$E, 'Date master'!$G:$G, "") | F14: =_xlfn.XLOOKUP(F11, 'Date master'!$E:$E,'Date master'!$F:$F, "") & " " & _xlfn.XLOOKUP(F11, 'Date master'!$E:$E, 'Date master'!$G:$G, "") | G14: =_xlfn.XLOOKUP(G11, 'Date master'!$E:$E,'Date master'!$F:$F, "") & " " & _xlfn.XLOOKUP(G11, 'Date master'!$E:$E, 'Date master'!$G:$G, "") | H14: =_xlfn.XLOOKUP(H11, 'Date master'!$E:$E,'Date master'!$F:$F, "") & " " & _xlfn.XLOOKUP(H11, 'Date master'!$E:$E, 'Date master'!$G:$G, "") -> US Independence Day
C15: =_xlfn.IFNA(_xlfn.XLOOKUP(C16,'Date master'!$E:$E,'Date master'!$I:$I),"") | D15: =_xlfn.IFNA(_xlfn.XLOOKUP(D16,'Date master'!$E:$E,'Date master'!$I:$I),"") -> 4 | E15: =_xlfn.IFNA(_xlfn.XLOOKUP(E16,'Date master'!$E:$E,'Date master'!$I:$I),"") -> 5 | F15: =_xlfn.IFNA(_xlfn.XLOOKUP(F16,'Date master'!$E:$E,'Date master'!$I:$I),"") -> 6 | G15: =_xlfn.IFNA(_xlfn.XLOOKUP(G16,'Date master'!$E:$E,'Date master'!$I:$I),"") -> 7 | H15: =_xlfn.IFNA(_xlfn.XLOOKUP(H16,'Date master'!$E:$E,'Date master'!$I:$I),"") -> 8 | I15: =_xlfn.IFNA(_xlfn.XLOOKUP(I16,'Date master'!$E:$E,'Date master'!$I:$I),"")
C16: =C11+7 -> 45844 | D16: =D11+7 -> 45845 | E16: =E11+7 -> 45846 | F16: =F11+7 -> 45847 | G16: =G11+7 -> 45848 | H16: =H11+7 -> 45849 | I16: =I11+7 -> 45850
C17: {=IFERROR( _xlfn.TEXTJOIN(CHAR(10), TRUE, _xlfn._xlws.FILTER( "- " & 'Commitments & Ownership Matrix'!$B$5:$B$30, ( ( ($I$7="Entire Team") * ('Commitments & Ownership Matrix'!$D$5:$D$30=C15) + (('Commitments & Ownership Matrix'!$F$5:$F$30=$I$7) * ('Commitments & Ownership Matrix'!$D$5:$D$30=C15)) ) * ('Commitments & Ownership Matrix'!$B$5:$B$30 <> "") ) ) ), "" )} | D17: {=IFERROR( _xlfn.TEXTJOIN(CHAR(10), TRUE, _xlfn._xlws.FILTER( "- " & 'Commitments & Ownership Matrix'!$B$5:$B$30, ( ( ($I$7="Entire Team") * ('Commitments & Ownership Matrix'!$D$5:$D$30=D15) + (('Commitments & Ownership Matrix'!$F$5:$F$30=$I$7) * ('Commitments & Ownership Matrix'!$D$5:$D$30=D15)) ) * ('Commitments & Ownership Matrix'!$B$5:$B$30 <> "") ) ) ), "" )} | E17: {=IFERROR( _xlfn.TEXTJOIN(CHAR(10), TRUE, _xlfn._xlws.FILTER( "- " & 'Commitments & Ownership Matrix'!$B$5:$B$30, ( ( ($I$7="Entire Team") * ('Commitments & Ownership Matrix'!$D$5:$D$30=E15) + (('Commitments & Ownership Matrix'!$F$5:$F$30=$I$7) * ('Commitments & Ownership Matrix'!$D$5:$D$30=E15)) ) * ('Commitments & Ownership Matrix'!$B$5:$B$30 <> "") ) ) ), "" )} -> - Accrued Expenses | F17: {=IFERROR( _xlfn.TEXTJOIN(CHAR(10), TRUE, _xlfn._xlws.FILTER( "- " & 'Commitments & Ownership Matrix'!$B$5:$B$30, ( ( ($I$7="Entire Team") * ('Commitments & Ownership Matrix'!$D$5:$D$30=F15) + (('Commitments & Ownership Matrix'!$F$5:$F$30=$I$7) * ('Commitments & Ownership Matrix'!$D$5:$D$30=F15)) ) * ('Commitments & Ownership Matrix'!$B$5:$B$30 <> "") ) ) ), "" )} -> - Banking | G17: {=IFERROR( _xlfn.TEXTJOIN(CHAR(10), TRUE, _xlfn._xlws.FILTER( "- " & 'Commitments & Ownership Matrix'!$B$5:$B$30, ( ( ($I$7="Entire Team") * ('Commitments & Ownership Matrix'!$D$5:$D$30=G15) + (('Commitments & Ownership Matrix'!$F$5:$F$30=$I$7) * ('Commitments & Ownership Matrix'!$D$5:$D$30=G15)) ) * ('Commitments & Ownership Matrix'!$B$5:$B$30 <> "") ) ) ), "" )} | H17: {=IFERROR( _xlfn.TEXTJOIN(CHAR(10), TRUE, _xlfn._xlws.FILTER( "- " & 'Commitments & Ownership Matrix'!$B$5:$B$30, ( ( ($I$7="Entire Team") * ('Commitments & Ownership Matrix'!$D$5:$D$30=H15) + (('Commitments & Ownership Matrix'!$F$5:$F$30=$I$7) * ('Commitments & Ownership Matrix'!$D$5:$D$30=H15)) ) * ('Commitments & Ownership Matrix'!$B$5:$B$30 <> "") ) ) ), "" )} | I17: {=IFERROR( _xlfn.TEXTJOIN(CHAR(10), TRUE, _xlfn._xlws.FILTER( "- " & 'Commitments & Ownership Matrix'!$B$5:$B$30, ( ( ($I$7="Entire Team") * ('Commitments & Ownership Matrix'!$D$5:$D$30=I15) + (('Commitments & Ownership Matrix'!$F$5:$F$30=$I$7) * ('Commitments & Ownership Matrix'!$D$5:$D$30=I15)) ) * ('Commitments & Ownership Matrix'!$B$5:$B$30 <> "") ) ) ), "" )}
C18: {=IFERROR( _xlfn.TEXTJOIN(CHAR(10), TRUE, _xlfn._xlws.FILTER( "- " & 'Commitments & Ownership Matrix'!$B$5:$B$40, ( (($I$7="Entire Team") * ('Commitments & Ownership Matrix'!$E$5:$E$40=C16)) + (('Commitments & Ownership Matrix'!$F$5:$F$40=$I$7) * ('Commitments & Ownership Matrix'!$E$5:$E$40=C16)) ) * ('Commitments & Ownership Matrix'!$H$5:$H$40="Exceptional") * ('Commitments & Ownership Matrix'!$B$5:$B$40<>"") ) ), "" )} | D18: {=IFERROR( _xlfn.TEXTJOIN(CHAR(10), TRUE, _xlfn._xlws.FILTER( "- " & 'Commitments & Ownership Matrix'!$B$5:$B$40, ( (($I$7="Entire Team") * ('Commitments & Ownership Matrix'!$E$5:$E$40=D16)) + (('Commitments & Ownership Matrix'!$F$5:$F$40=$I$7) * ('Commitments & Ownership Matrix'!$E$5:$E$40=D16)) ) * ('Commitments & Ownership Matrix'!$H$5:$H$40="Exceptional") * ('Commitments & Ownership Matrix'!$B$5:$B$40<>"") ) ), "" )} | E18: {=IFERROR( _xlfn.TEXTJOIN(CHAR(10), TRUE, _xlfn._xlws.FILTER( "- " & 'Commitments & Ownership Matrix'!$B$5:$B$40, ( (($I$7="Entire Team") * ('Commitments & Ownership Matrix'!$E$5:$E$40=E16)) + (('Commitments & Ownership Matrix'!$F$5:$F$40=$I$7) * ('Commitments & Ownership Matrix'!$E$5:$E$40=E16)) ) * ('Commitments & Ownership Matrix'!$H$5:$H$40="Exceptional") * ('Commitments & Ownership Matrix'!$B$5:$B$40<>"") ) ), "" )} | F18: {=IFERROR( _xlfn.TEXTJOIN(CHAR(10), TRUE, _xlfn._xlws.FILTER( "- " & 'Commitments & Ownership Matrix'!$B$5:$B$40, ( (($I$7="Entire Team") * ('Commitments & Ownership Matrix'!$E$5:$E$40=F16)) + (('Commitments & Ownership Matrix'!$F$5:$F$40=$I$7) * ('Commitments & Ownership Matrix'!$E$5:$E$40=F16)) ) * ('Commitments & Ownership Matrix'!$H$5:$H$40="Exceptional") * ('Commitments & Ownership Matrix'!$B$5:$B$40<>"") ) ), "" )} | G18: {=IFERROR( _xlfn.TEXTJOIN(CHAR(10), TRUE, _xlfn._xlws.FILTER( "- " & 'Commitments & Ownership Matrix'!$B$5:$B$40, ( (($I$7="Entire Team") * ('Commitments & Ownership Matrix'!$E$5:$E$40=G16)) + (('Commitments & Ownership Matrix'!$F$5:$F$40=$I$7) * ('Commitments & Ownership Matrix'!$E$5:$E$40=G16)) ) * ('Commitments & Ownership Matrix'!$H$5:$H$40="Exceptional") * ('Commitments & Ownership Matrix'!$B$5:$B$40<>"") ) ), "" )} | H18: {=IFERROR( _xlfn.TEXTJOIN(CHAR(10), TRUE, _xlfn._xlws.FILTER( "- " & 'Commitments & Ownership Matrix'!$B$5:$B$40, ( (($I$7="Entire Team") * ('Commitments & Ownership Matrix'!$E$5:$E$40=H16)) + (('Commitments & Ownership Matrix'!$F$5:$F$40=$I$7) * ('Commitments & Ownership Matrix'!$E$5:$E$40=H16)) ) * ('Commitments & Ownership Matrix'!$H$5:$H$40="Exceptional") * ('Commitments & Ownership Matrix'!$B$5:$B$40<>"") ) ), "" )} | I18: {=IFERROR( _xlfn.TEXTJOIN(CHAR(10), TRUE, _xlfn._xlws.FILTER( "- " & 'Commitments & Ownership Matrix'!$B$5:$B$40, ( (($I$7="Entire Team") * ('Commitments & Ownership Matrix'!$E$5:$E$40=I16)) + (('Commitments & Ownership Matrix'!$F$5:$F$40=$I$7) * ('Commitments & Ownership Matrix'!$E$5:$E$40=I16)) ) * ('Commitments & Ownership Matrix'!$H$5:$H$40="Exceptional") * ('Commitments & Ownership Matrix'!$B$5:$B$40<>"") ) ), "" )}
D19: =_xlfn.XLOOKUP(D16, 'Date master'!$E:$E,'Date master'!$F:$F, "") & " " & _xlfn.XLOOKUP(D16, 'Date master'!$E:$E, 'Date master'!$G:$G, "") | E19: =_xlfn.XLOOKUP(E16, 'Date master'!$E:$E,'Date master'!$F:$F, "") & " " & _xlfn.XLOOKUP(E16, 'Date master'!$E:$E, 'Date master'!$G:$G, "") | F19: =_xlfn.XLOOKUP(F16, 'Date master'!$E:$E,'Date master'!$F:$F, "") & " " & _xlfn.XLOOKUP(F16, 'Date master'!$E:$E, 'Date master'!$G:$G, "") | G19: =_xlfn.XLOOKUP(G16, 'Date master'!$E:$E,'Date master'!$F:$F, "") & " " & _xlfn.XLOOKUP(G16, 'Date master'!$E:$E, 'Date master'!$G:$G, "") | H19: =_xlfn.XLOOKUP(H16, 'Date master'!$E:$E,'Date master'!$F:$F, "") & " " & _xlfn.XLOOKUP(H16, 'Date master'!$E:$E, 'Date master'!$G:$G, "")
C20: =_xlfn.IFNA(_xlfn.XLOOKUP(C21,'Date master'!$E:$E,'Date master'!$I:$I),"") | D20: =_xlfn.IFNA(_xlfn.XLOOKUP(D21,'Date master'!$E:$E,'Date master'!$I:$I),"") -> 9 | E20: =_xlfn.IFNA(_xlfn.XLOOKUP(E21,'Date master'!$E:$E,'Date master'!$I:$I),"") -> 10 | F20: =_xlfn.IFNA(_xlfn.XLOOKUP(F21,'Date master'!$E:$E,'Date master'!$I:$I),"") -> 11 | G20: =_xlfn.IFNA(_xlfn.XLOOKUP(G21,'Date master'!$E:$E,'Date master'!$I:$I),"") -> 12 | H20: =_xlfn.IFNA(_xlfn.XLOOKUP(H21,'Date master'!$E:$E,'Date master'!$I:$I),"") -> 13 | I20: =_xlfn.IFNA(_xlfn.XLOOKUP(I21,'Date master'!$E:$E,'Date master'!$I:$I),"")
C21: =C16+7 -> 45851 | D21: =D16+7 -> 45852 | E21: =E16+7 -> 45853 | F21: =F16+7 -> 45854 | G21: =G16+7 -> 45855 | H21: =H16+7 -> 45856 | I21: =I16+7 -> 45857
C22: {=IFERROR( _xlfn.TEXTJOIN(CHAR(10), TRUE, _xlfn._xlws.FILTER( "- " & 'Commitments & Ownership Matrix'!$B$5:$B$30, ( ( ($I$7="Entire Team") * ('Commitments & Ownership Matrix'!$D$5:$D$30=C20) + (('Commitments & Ownership Matrix'!$F$5:$F$30=$I$7) * ('Commitments & Ownership Matrix'!$D$5:$D$30=C20)) ) * ('Commitments & Ownership Matrix'!$B$5:$B$30 <> "") ) ) ), "" )} | D22: {=IFERROR( _xlfn.TEXTJOIN(CHAR(10), TRUE, _xlfn._xlws.FILTER( "- " & 'Commitments & Ownership Matrix'!$B$5:$B$30, ( ( ($I$7="Entire Team") * ('Commitments & Ownership Matrix'!$D$5:$D$30=D20) + (('Commitments & Ownership Matrix'!$F$5:$F$30=$I$7) * ('Commitments & Ownership Matrix'!$D$5:$D$30=D20)) ) * ('Commitments & Ownership Matrix'!$B$5:$B$30 <> "") ) ) ), "" )} | E22: {=IFERROR( _xlfn.TEXTJOIN(CHAR(10), TRUE, _xlfn._xlws.FILTER( "- " & 'Commitments & Ownership Matrix'!$B$5:$B$30, ( ( ($I$7="Entire Team") * ('Commitments & Ownership Matrix'!$D$5:$D$30=E20) + (('Commitments & Ownership Matrix'!$F$5:$F$30=$I$7) * ('Commitments & Ownership Matrix'!$D$5:$D$30=E20)) ) * ('Commitments & Ownership Matrix'!$B$5:$B$30 <> "") ) ) ), "" )} | F22: {=IFERROR( _xlfn.TEXTJOIN(CHAR(10), TRUE, _xlfn._xlws.FILTER( "- " & 'Commitments & Ownership Matrix'!$B$5:$B$30, ( ( ($I$7="Entire Team") * ('Commitments & Ownership Matrix'!$D$5:$D$30=F20) + (('Commitments & Ownership Matrix'!$F$5:$F$30=$I$7) * ('Commitments & Ownership Matrix'!$D$5:$D$30=F20)) ) * ('Commitments & Ownership Matrix'!$B$5:$B$30 <> "") ) ) ), "" )} | G22: {=IFERROR( _xlfn.TEXTJOIN(CHAR(10), TRUE, _xlfn._xlws.FILTER( "- " & 'Commitments & Ownership Matrix'!$B$5:$B$30, ( ( ($I$7="Entire Team") * ('Commitments & Ownership Matrix'!$D$5:$D$30=G20) + (('Commitments & Ownership Matrix'!$F$5:$F$30=$I$7) * ('Commitments & Ownership Matrix'!$D$5:$D$30=G20)) ) * ('Commitments & Ownership Matrix'!$B$5:$B$30 <> "") ) ) ), "" )} | H22: {=IFERROR( _xlfn.TEXTJOIN(CHAR(10), TRUE, _xlfn._xlws.FILTER( "- " & 'Commitments & Ownership Matrix'!$B$5:$B$30, ( ( ($I$7="Entire Team") * ('Commitments & Ownership Matrix'!$D$5:$D$30=H20) + (('Commitments & Ownership Matrix'!$F$5:$F$30=$I$7) * ('Commitments & Ownership Matrix'!$D$5:$D$30=H20)) ) * ('Commitments & Ownership Matrix'!$B$5:$B$30 <> "") ) ) ), "" )} | I22: {=IFERROR( _xlfn.TEXTJOIN(CHAR(10), TRUE, _xlfn._xlws.FILTER( "- " & 'Commitments & Ownership Matrix'!$B$5:$B$30, ( ( ($I$7="Entire Team") * ('Commitments & Ownership Matrix'!$D$5:$D$30=I20) + (('Commitments & Ownership Matrix'!$F$5:$F$30=$I$7) * ('Commitments & Ownership Matrix'!$D$5:$D$30=I20)) ) * ('Commitments & Ownership Matrix'!$B$5:$B$30 <> "") ) ) ), "" )}
C23: {=IFERROR( _xlfn.TEXTJOIN(CHAR(10), TRUE, _xlfn._xlws.FILTER( "- " & 'Commitments & Ownership Matrix'!$B$5:$B$40, ( (($I$7="Entire Team") * ('Commitments & Ownership Matrix'!$E$5:$E$40=C21)) + (('Commitments & Ownership Matrix'!$F$5:$F$40=$I$7) * ('Commitments & Ownership Matrix'!$E$5:$E$40=C21)) ) * ('Commitments & Ownership Matrix'!$H$5:$H$40="Exceptional") * ('Commitments & Ownership Matrix'!$B$5:$B$40<>"") ) ), "" )} | D23: {=IFERROR( _xlfn.TEXTJOIN(CHAR(10), TRUE, _xlfn._xlws.FILTER( "- " & 'Commitments & Ownership Matrix'!$B$5:$B$40, ( (($I$7="Entire Team") * ('Commitments & Ownership Matrix'!$E$5:$E$40=D21)) + (('Commitments & Ownership Matrix'!$F$5:$F$40=$I$7) * ('Commitments & Ownership Matrix'!$E$5:$E$40=D21)) ) * ('Commitments & Ownership Matrix'!$H$5:$H$40="Exceptional") * ('Commitments & Ownership Matrix'!$B$5:$B$40<>"") ) ), "" )} | E23: {=IFERROR( _xlfn.TEXTJOIN(CHAR(10), TRUE, _xlfn._xlws.FILTER( "- " & 'Commitments & Ownership Matrix'!$B$5:$B$40, ( (($I$7="Entire Team") * ('Commitments & Ownership Matrix'!$E$5:$E$40=E21)) + (('Commitments & Ownership Matrix'!$F$5:$F$40=$I$7) * ('Commitments & Ownership Matrix'!$E$5:$E$40=E21)) ) * ('Commitments & Ownership Matrix'!$H$5:$H$40="Exceptional") * ('Commitments & Ownership Matrix'!$B$5:$B$40<>"") ) ), "" )} | F23: {=IFERROR( _xlfn.TEXTJOIN(CHAR(10), TRUE, _xlfn._xlws.FILTER( "- " & 'Commitments & Ownership Matrix'!$B$5:$B$40, ( (($I$7="Entire Team") * ('Commitments & Ownership Matrix'!$E$5:$E$40=F21)) + (('Commitments & Ownership Matrix'!$F$5:$F$40=$I$7) * ('Commitments & Ownership Matrix'!$E$5:$E$40=F21)) ) * ('Commitments & Ownership Matrix'!$H$5:$H$40="Exceptional") * ('Commitments & Ownership Matrix'!$B$5:$B$40<>"") ) ), "" )} | G23: {=IFERROR( _xlfn.TEXTJOIN(CHAR(10), TRUE, _xlfn._xlws.FILTER( "- " & 'Commitments & Ownership Matrix'!$B$5:$B$40, ( (($I$7="Entire Team") * ('Commitments & Ownership Matrix'!$E$5:$E$40=G21)) + (('Commitments & Ownership Matrix'!$F$5:$F$40=$I$7) * ('Commitments & Ownership Matrix'!$E$5:$E$40=G21)) ) * ('Commitments & Ownership Matrix'!$H$5:$H$40="Exceptional") * ('Commitments & Ownership Matrix'!$B$5:$B$40<>"") ) ), "" )} | H23: {=IFERROR( _xlfn.TEXTJOIN(CHAR(10), TRUE, _xlfn._xlws.FILTER( "- " & 'Commitments & Ownership Matrix'!$B$5:$B$40, ( (($I$7="Entire Team") * ('Commitments & Ownership Matrix'!$E$5:$E$40=H21)) + (('Commitments & Ownership Matrix'!$F$5:$F$40=$I$7) * ('Commitments & Ownership Matrix'!$E$5:$E$40=H21)) ) * ('Commitments & Ownership Matrix'!$H$5:$H$40="Exceptional") * ('Commitments & Ownership Matrix'!$B$5:$B$40<>"") ) ), "" )} | I23: {=IFERROR( _xlfn.TEXTJOIN(CHAR(10), TRUE, _xlfn._xlws.FILTER( "- " & 'Commitments & Ownership Matrix'!$B$5:$B$40, ( (($I$7="Entire Team") * ('Commitments & Ownership Matrix'!$E$5:$E$40=I21)) + (('Commitments & Ownership Matrix'!$F$5:$F$40=$I$7) * ('Commitments & Ownership Matrix'!$E$5:$E$40=I21)) ) * ('Commitments & Ownership Matrix'!$H$5:$H$40="Exceptional") * ('Commitments & Ownership Matrix'!$B$5:$B$40<>"") ) ), "" )}
D24: =_xlfn.XLOOKUP(D21, 'Date master'!$E:$E,'Date master'!$F:$F, "") & " " & _xlfn.XLOOKUP(D21, 'Date master'!$E:$E, 'Date master'!$G:$G, "") | E24: =_xlfn.XLOOKUP(E21, 'Date master'!$E:$E,'Date master'!$F:$F, "") & " " & _xlfn.XLOOKUP(E21, 'Date master'!$E:$E, 'Date master'!$G:$G, "") | F24: =_xlfn.XLOOKUP(F21, 'Date master'!$E:$E,'Date master'!$F:$F, "") & " " & _xlfn.XLOOKUP(F21, 'Date master'!$E:$E, 'Date master'!$G:$G, "") | G24: =_xlfn.XLOOKUP(G21, 'Date master'!$E:$E,'Date master'!$F:$F, "") & " " & _xlfn.XLOOKUP(G21, 'Date master'!$E:$E, 'Date master'!$G:$G, "") | H24: =_xlfn.XLOOKUP(H21, 'Date master'!$E:$E,'Date master'!$F:$F, "") & " " & _xlfn.XLOOKUP(H21, 'Date master'!$E:$E, 'Date master'!$G:$G, "")
C25: =_xlfn.IFNA(_xlfn.XLOOKUP(C26,'Date master'!$E:$E,'Date master'!$I:$I),"") | D25: =_xlfn.IFNA(_xlfn.XLOOKUP(D26,'Date master'!$E:$E,'Date master'!$I:$I),"") -> 14 | E25: =_xlfn.IFNA(_xlfn.XLOOKUP(E26,'Date master'!$E:$E,'Date master'!$I:$I),"") -> 15 | F25: =_xlfn.IFNA(_xlfn.XLOOKUP(F26,'Date master'!$E:$E,'Date master'!$I:$I),"") -> 16 | G25: =_xlfn.IFNA(_xlfn.XLOOKUP(G26,'Date master'!$E:$E,'Date master'!$I:$I),"") -> 17 | H25: =_xlfn.IFNA(_xlfn.XLOOKUP(H26,'Date master'!$E:$E,'Date master'!$I:$I),"") -> 18 | I25: =_xlfn.IFNA(_xlfn.XLOOKUP(I26,'Date master'!$E:$E,'Date master'!$I:$I),"")
C26: =C21+7 -> 45858 | D26: =D21+7 -> 45859 | E26: =E21+7 -> 45860 | F26: =F21+7 -> 45861 | G26: =G21+7 -> 45862 | H26: =H21+7 -> 45863 | I26: =I21+7 -> 45864
C27: {=IFERROR( _xlfn.TEXTJOIN(CHAR(10), TRUE, _xlfn._xlws.FILTER( "- " & 'Commitments & Ownership Matrix'!$B$5:$B$30, ( ( ($I$7="Entire Team") * ('Commitments & Ownership Matrix'!$D$5:$D$30=C25) + (('Commitments & Ownership Matrix'!$F$5:$F$30=$I$7) * ('Commitments & Ownership Matrix'!$D$5:$D$30=C25)) ) * ('Commitments & Ownership Matrix'!$B$5:$B$30 <> "") ) ) ), "" )} | D27: {=IFERROR( _xlfn.TEXTJOIN(CHAR(10), TRUE, _xlfn._xlws.FILTER( "- " & 'Commitments & Ownership Matrix'!$B$5:$B$30, ( ( ($I$7="Entire Team") * ('Commitments & Ownership Matrix'!$D$5:$D$30=D25) + (('Commitments & Ownership Matrix'!$F$5:$F$30=$I$7) * ('Commitments & Ownership Matrix'!$D$5:$D$30=D25)) ) * ('Commitments & Ownership Matrix'!$B$5:$B$30 <> "") ) ) ), "" )} | E27: {=IFERROR( _xlfn.TEXTJOIN(CHAR(10), TRUE, _xlfn._xlws.FILTER( "- " & 'Commitments & Ownership Matrix'!$B$5:$B$30, ( ( ($I$7="Entire Team") * ('Commitments & Ownership Matrix'!$D$5:$D$30=E25) + (('Commitments & Ownership Matrix'!$F$5:$F$30=$I$7) * ('Commitments & Ownership Matrix'!$D$5:$D$30=E25)) ) * ('Commitments & Ownership Matrix'!$B$5:$B$30 <> "") ) ) ), "" )} | F27: {=IFERROR( _xlfn.TEXTJOIN(CHAR(10), TRUE, _xlfn._xlws.FILTER( "- " & 'Commitments & Ownership Matrix'!$B$5:$B$30, ( ( ($I$7="Entire Team") * ('Commitments & Ownership Matrix'!$D$5:$D$30=F25) + (('Commitments & Ownership Matrix'!$F$5:$F$30=$I$7) * ('Commitments & Ownership Matrix'!$D$5:$D$30=F25)) ) * ('Commitments & Ownership Matrix'!$B$5:$B$30 <> "") ) ) ), "" )} | G27: {=IFERROR( _xlfn.TEXTJOIN(CHAR(10), TRUE, _xlfn._xlws.FILTER( "- " & 'Commitments & Ownership Matrix'!$B$5:$B$30, ( ( ($I$7="Entire Team") * ('Commitments & Ownership Matrix'!$D$5:$D$30=G25) + (('Commitments & Ownership Matrix'!$F$5:$F$30=$I$7) * ('Commitments & Ownership Matrix'!$D$5:$D$30=G25)) ) * ('Commitments & Ownership Matrix'!$B$5:$B$30 <> "") ) ) ), "" )} | H27: {=IFERROR( _xlfn.TEXTJOIN(CHAR(10), TRUE, _xlfn._xlws.FILTER( "- " & 'Commitments & Ownership Matrix'!$B$5:$B$30, ( ( ($I$7="Entire Team") * ('Commitments & Ownership Matrix'!$D$5:$D$30=H25) + (('Commitments & Ownership Matrix'!$F$5:$F$30=$I$7) * ('Commitments & Ownership Matrix'!$D$5:$D$30=H25)) ) * ('Commitments & Ownership Matrix'!$B$5:$B$30 <> "") ) ) ), "" )} | I27: {=IFERROR( _xlfn.TEXTJOIN(CHAR(10), TRUE, _xlfn._xlws.FILTER( "- " & 'Commitments & Ownership Matrix'!$B$5:$B$30, ( ( ($I$7="Entire Team") * ('Commitments & Ownership Matrix'!$D$5:$D$30=I25) + (('Commitments & Ownership Matrix'!$F$5:$F$30=$I$7) * ('Commitments & Ownership Matrix'!$D$5:$D$30=I25)) ) * ('Commitments & Ownership Matrix'!$B$5:$B$30 <> "") ) ) ), "" )}
C28: {=IFERROR( _xlfn.TEXTJOIN(CHAR(10), TRUE, _xlfn._xlws.FILTER( "- " & 'Commitments & Ownership Matrix'!$B$5:$B$40, ( (($I$7="Entire Team") * ('Commitments & Ownership Matrix'!$E$5:$E$40=C26)) + (('Commitments & Ownership Matrix'!$F$5:$F$40=$I$7) * ('Commitments & Ownership Matrix'!$E$5:$E$40=C26)) ) * ('Commitments & Ownership Matrix'!$H$5:$H$40="Exceptional") * ('Commitments & Ownership Matrix'!$B$5:$B$40<>"") ) ), "" )} | D28: {=IFERROR( _xlfn.TEXTJOIN(CHAR(10), TRUE, _xlfn._xlws.FILTER( "- " & 'Commitments & Ownership Matrix'!$B$5:$B$40, ( (($I$7="Entire Team") * ('Commitments & Ownership Matrix'!$E$5:$E$40=D26)) + (('Commitments & Ownership Matrix'!$F$5:$F$40=$I$7) * ('Commitments & Ownership Matrix'!$E$5:$E$40=D26)) ) * ('Commitments & Ownership Matrix'!$H$5:$H$40="Exceptional") * ('Commitments & Ownership Matrix'!$B$5:$B$40<>"") ) ), "" )} | E28: {=IFERROR( _xlfn.TEXTJOIN(CHAR(10), TRUE, _xlfn._xlws.FILTER( "- " & 'Commitments & Ownership Matrix'!$B$5:$B$40, ( (($I$7="Entire Team") * ('Commitments & Ownership Matrix'!$E$5:$E$40=E26)) + (('Commitments & Ownership Matrix'!$F$5:$F$40=$I$7) * ('Commitments & Ownership Matrix'!$E$5:$E$40=E26)) ) * ('Commitments & Ownership Matrix'!$H$5:$H$40="Exceptional") * ('Commitments & Ownership Matrix'!$B$5:$B$40<>"") ) ), "" )} | F28: {=IFERROR( _xlfn.TEXTJOIN(CHAR(10), TRUE, _xlfn._xlws.FILTER( "- " & 'Commitments & Ownership Matrix'!$B$5:$B$40, ( (($I$7="Entire Team") * ('Commitments & Ownership Matrix'!$E$5:$E$40=F26)) + (('Commitments & Ownership Matrix'!$F$5:$F$40=$I$7) * ('Commitments & Ownership Matrix'!$E$5:$E$40=F26)) ) * ('Commitments & Ownership Matrix'!$H$5:$H$40="Exceptional") * ('Commitments & Ownership Matrix'!$B$5:$B$40<>"") ) ), "" )} | G28: {=IFERROR( _xlfn.TEXTJOIN(CHAR(10), TRUE, _xlfn._xlws.FILTER( "- " & 'Commitments & Ownership Matrix'!$B$5:$B$40, ( (($I$7="Entire Team") * ('Commitments & Ownership Matrix'!$E$5:$E$40=G26)) + (('Commitments & Ownership Matrix'!$F$5:$F$40=$I$7) * ('Commitments & Ownership Matrix'!$E$5:$E$40=G26)) ) * ('Commitments & Ownership Matrix'!$H$5:$H$40="Exceptional") * ('Commitments & Ownership Matrix'!$B$5:$B$40<>"") ) ), "" )} | H28: {=IFERROR( _xlfn.TEXTJOIN(CHAR(10), TRUE, _xlfn._xlws.FILTER( "- " & 'Commitments & Ownership Matrix'!$B$5:$B$40, ( (($I$7="Entire Team") * ('Commitments & Ownership Matrix'!$E$5:$E$40=H26)) + (('Commitments & Ownership Matrix'!$F$5:$F$40=$I$7) * ('Commitments & Ownership Matrix'!$E$5:$E$40=H26)) ) * ('Commitments & Ownership Matrix'!$H$5:$H$40="Exceptional") * ('Commitments & Ownership Matrix'!$B$5:$B$40<>"") ) ), "" )} | I28: {=IFERROR( _xlfn.TEXTJOIN(CHAR(10), TRUE, _xlfn._xlws.FILTER( "- " & 'Commitments & Ownership Matrix'!$B$5:$B$40, ( (($I$7="Entire Team") * ('Commitments & Ownership Matrix'!$E$5:$E$40=I26)) + (('Commitments & Ownership Matrix'!$F$5:$F$40=$I$7) * ('Commitments & Ownership Matrix'!$E$5:$E$40=I26)) ) * ('Commitments & Ownership Matrix'!$H$5:$H$40="Exceptional") * ('Commitments & Ownership Matrix'!$B$5:$B$40<>"") ) ), "" )}
D29: =_xlfn.XLOOKUP(D26, 'Date master'!$E:$E,'Date master'!$F:$F, "") & " " & _xlfn.XLOOKUP(D26, 'Date master'!$E:$E, 'Date master'!$G:$G, "") | E29: =_xlfn.XLOOKUP(E26, 'Date master'!$E:$E,'Date master'!$F:$F, "") & " " & _xlfn.XLOOKUP(E26, 'Date master'!$E:$E, 'Date master'!$G:$G, "") | F29: =_xlfn.XLOOKUP(F26, 'Date master'!$E:$E,'Date master'!$F:$F, "") & " " & _xlfn.XLOOKUP(F26, 'Date master'!$E:$E, 'Date master'!$G:$G, "") | G29: =_xlfn.XLOOKUP(G26, 'Date master'!$E:$E,'Date master'!$F:$F, "") & " " & _xlfn.XLOOKUP(G26, 'Date master'!$E:$E, 'Date master'!$G:$G, "") | H29: =_xlfn.XLOOKUP(H26, 'Date master'!$E:$E,'Date master'!$F:$F, "") & " " & _xlfn.XLOOKUP(H26, 'Date master'!$E:$E, 'Date master'!$G:$G, "")
C30: =_xlfn.IFNA(_xlfn.XLOOKUP(C31,'Date master'!$E:$E,'Date master'!$I:$I),"") | D30: =_xlfn.IFNA(_xlfn.XLOOKUP(D31,'Date master'!$E:$E,'Date master'!$I:$I),"") -> 19 | E30: =_xlfn.IFNA(_xlfn.XLOOKUP(E31,'Date master'!$E:$E,'Date master'!$I:$I),"") -> 20 | F30: =_xlfn.IFNA(_xlfn.XLOOKUP(F31,'Date master'!$E:$E,'Date master'!$I:$I),"") -> 21 | G30: =_xlfn.IFNA(_xlfn.XLOOKUP(G31,'Date master'!$E:$E,'Date master'!$I:$I),"") -> 22 | H30: =_xlfn.IFNA(_xlfn.XLOOKUP(H31,'Date master'!$E:$E,'Date master'!$I:$I),"") -> 1 | I30: =_xlfn.IFNA(_xlfn.XLOOKUP(I31,'Date master'!$E:$E,'Date master'!$I:$I),"")
C31: =C26+7 -> 45865 | D31: =D26+7 -> 45866 | E31: =E26+7 -> 45867 | F31: =F26+7 -> 45868 | G31: =G26+7 -> 45869 | H31: =H26+7 -> 45870 | I31: =I26+7 -> 45871
C32: {=IFERROR( _xlfn.TEXTJOIN(CHAR(10), TRUE, _xlfn._xlws.FILTER( "- " & 'Commitments & Ownership Matrix'!$B$5:$B$30, ( ( ($I$7="Entire Team") * ('Commitments & Ownership Matrix'!$D$5:$D$30=C30) + (('Commitments & Ownership Matrix'!$F$5:$F$30=$I$7) * ('Commitments & Ownership Matrix'!$D$5:$D$30=C30)) ) * ('Commitments & Ownership Matrix'!$B$5:$B$30 <> "") ) ) ), "" )} | D32: {=IFERROR( _xlfn.TEXTJOIN(CHAR(10), TRUE, _xlfn._xlws.FILTER( "- " & 'Commitments & Ownership Matrix'!$B$5:$B$30, ( ( ($I$7="Entire Team") * ('Commitments & Ownership Matrix'!$D$5:$D$30=D30) + (('Commitments & Ownership Matrix'!$F$5:$F$30=$I$7) * ('Commitments & Ownership Matrix'!$D$5:$D$30=D30)) ) * ('Commitments & Ownership Matrix'!$B$5:$B$30 <> "") ) ) ), "" )} | E32: {=IFERROR( _xlfn.TEXTJOIN(CHAR(10), TRUE, _xlfn._xlws.FILTER( "- " & 'Commitments & Ownership Matrix'!$B$5:$B$30, ( ( ($I$7="Entire Team") * ('Commitments & Ownership Matrix'!$D$5:$D$30=E30) + (('Commitments & Ownership Matrix'!$F$5:$F$30=$I$7) * ('Commitments & Ownership Matrix'!$D$5:$D$30=E30)) ) * ('Commitments & Ownership Matrix'!$B$5:$B$30 <> "") ) ) ), "" )} | F32: {=IFERROR( _xlfn.TEXTJOIN(CHAR(10), TRUE, _xlfn._xlws.FILTER( "- " & 'Commitments & Ownership Matrix'!$B$5:$B$30, ( ( ($I$7="Entire Team") * ('Commitments & Ownership Matrix'!$D$5:$D$30=F30) + (('Commitments & Ownership Matrix'!$F$5:$F$30=$I$7) * ('Commitments & Ownership Matrix'!$D$5:$D$30=F30)) ) * ('Commitments & Ownership Matrix'!$B$5:$B$30 <> "") ) ) ), "" )} | G32: {=IFERROR( _xlfn.TEXTJOIN(CHAR(10), TRUE, _xlfn._xlws.FILTER( "- " & 'Commitments & Ownership Matrix'!$B$5:$B$30, ( ( ($I$7="Entire Team") * ('Commitments & Ownership Matrix'!$D$5:$D$30=G30) + (('Commitments & Ownership Matrix'!$F$5:$F$30=$I$7) * ('Commitments & Ownership Matrix'!$D$5:$D$30=G30)) ) * ('Commitments & Ownership Matrix'!$B$5:$B$30 <> "") ) ) ), "" )} | H32: {=IFERROR( _xlfn.TEXTJOIN(CHAR(10), TRUE, _xlfn._xlws.FILTER( "- " & 'Commitments & Ownership Matrix'!$B$5:$B$30, ( ( ($I$7="Entire Team") * ('Commitments & Ownership Matrix'!$D$5:$D$30=H30) + (('Commitments & Ownership Matrix'!$F$5:$F$30=$I$7) * ('Commitments & Ownership Matrix'!$D$5:$D$30=H30)) ) * ('Commitments & Ownership Matrix'!$B$5:$B$30 <> "") ) ) ), "" )} | I32: {=IFERROR( _xlfn.TEXTJOIN(CHAR(10), TRUE, _xlfn._xlws.FILTER( "- " & 'Commitments & Ownership Matrix'!$B$5:$B$30, ( ( ($I$7="Entire Team") * ('Commitments & Ownership Matrix'!$D$5:$D$30=I30) + (('Commitments & Ownership Matrix'!$F$5:$F$30=$I$7) * ('Commitments & Ownership Matrix'!$D$5:$D$30=I30)) ) * ('Commitments & Ownership Matrix'!$B$5:$B$30 <> "") ) ) ), "" )}
C33: {=IFERROR( _xlfn.TEXTJOIN(CHAR(10), TRUE, _xlfn._xlws.FILTER( "- " & 'Commitments & Ownership Matrix'!$B$5:$B$40, ( (($I$7="Entire Team") * ('Commitments & Ownership Matrix'!$E$5:$E$40=C31)) + (('Commitments & Ownership Matrix'!$F$5:$F$40=$I$7) * ('Commitments & Ownership Matrix'!$E$5:$E$40=C31)) ) * ('Commitments & Ownership Matrix'!$H$5:$H$40="Exceptional") * ('Commitments & Ownership Matrix'!$B$5:$B$40<>"") ) ), "" )} | D33: {=IFERROR( _xlfn.TEXTJOIN(CHAR(10), TRUE, _xlfn._xlws.FILTER( "- " & 'Commitments & Ownership Matrix'!$B$5:$B$40, ( (($I$7="Entire Team") * ('Commitments & Ownership Matrix'!$E$5:$E$40=D31)) + (('Commitments & Ownership Matrix'!$F$5:$F$40=$I$7) * ('Commitments & Ownership Matrix'!$E$5:$E$40=D31)) ) * ('Commitments & Ownership Matrix'!$H$5:$H$40="Exceptional") * ('Commitments & Ownership Matrix'!$B$5:$B$40<>"") ) ), "" )} | E33: {=IFERROR( _xlfn.TEXTJOIN(CHAR(10), TRUE, _xlfn._xlws.FILTER( "- " & 'Commitments & Ownership Matrix'!$B$5:$B$40, ( (($I$7="Entire Team") * ('Commitments & Ownership Matrix'!$E$5:$E$40=E31)) + (('Commitments & Ownership Matrix'!$F$5:$F$40=$I$7) * ('Commitments & Ownership Matrix'!$E$5:$E$40=E31)) ) * ('Commitments & Ownership Matrix'!$H$5:$H$40="Exceptional") * ('Commitments & Ownership Matrix'!$B$5:$B$40<>"") ) ), "" )} | F33: {=IFERROR( _xlfn.TEXTJOIN(CHAR(10), TRUE, _xlfn._xlws.FILTER( "- " & 'Commitments & Ownership Matrix'!$B$5:$B$40, ( (($I$7="Entire Team") * ('Commitments & Ownership Matrix'!$E$5:$E$40=F31)) + (('Commitments & Ownership Matrix'!$F$5:$F$40=$I$7) * ('Commitments & Ownership Matrix'!$E$5:$E$40=F31)) ) * ('Commitments & Ownership Matrix'!$H$5:$H$40="Exceptional") * ('Commitments & Ownership Matrix'!$B$5:$B$40<>"") ) ), "" )} | G33: {=IFERROR( _xlfn.TEXTJOIN(CHAR(10), TRUE, _xlfn._xlws.FILTER( "- " & 'Commitments & Ownership Matrix'!$B$5:$B$40, ( (($I$7="Entire Team") * ('Commitments & Ownership Matrix'!$E$5:$E$40=G31)) + (('Commitments & Ownership Matrix'!$F$5:$F$40=$I$7) * ('Commitments & Ownership Matrix'!$E$5:$E$40=G31)) ) * ('Commitments & Ownership Matrix'!$H$5:$H$40="Exceptional") * ('Commitments & Ownership Matrix'!$B$5:$B$40<>"") ) ), "" )} | H33: {=IFERROR( _xlfn.TEXTJOIN(CHAR(10), TRUE, _xlfn._xlws.FILTER( "- " & 'Commitments & Ownership Matrix'!$B$5:$B$40, ( (($I$7="Entire Team") * ('Commitments & Ownership Matrix'!$E$5:$E$40=H31)) + (('Commitments & Ownership Matrix'!$F$5:$F$40=$I$7) * ('Commitments & Ownership Matrix'!$E$5:$E$40=H31)) ) * ('Commitments & Ownership Matrix'!$H$5:$H$40="Exceptional") * ('Commitments & Ownership Matrix'!$B$5:$B$40<>"") ) ), "" )} | I33: {=IFERROR( _xlfn.TEXTJOIN(CHAR(10), TRUE, _xlfn._xlws.FILTER( "- " & 'Commitments & Ownership Matrix'!$B$5:$B$40, ( (($I$7="Entire Team") * ('Commitments & Ownership Matrix'!$E$5:$E$40=I31)) + (('Commitments & Ownership Matrix'!$F$5:$F$40=$I$7) * ('Commitments & Ownership Matrix'!$E$5:$E$40=I31)) ) * ('Commitments & Ownership Matrix'!$H$5:$H$40="Exceptional") * ('Commitments & Ownership Matrix'!$B$5:$B$40<>"") ) ), "" )}
D34: =_xlfn.XLOOKUP(D31, 'Date master'!$E:$E,'Date master'!$F:$F, "") & " " & _xlfn.XLOOKUP(D31, 'Date master'!$E:$E, 'Date master'!$G:$G, "") | E34: =_xlfn.XLOOKUP(E31, 'Date master'!$E:$E,'Date master'!$F:$F, "") & " " & _xlfn.XLOOKUP(E31, 'Date master'!$E:$E, 'Date master'!$G:$G, "") | F34: =_xlfn.XLOOKUP(F31, 'Date master'!$E:$E,'Date master'!$F:$F, "") & " " & _xlfn.XLOOKUP(F31, 'Date master'!$E:$E, 'Date master'!$G:$G, "") | G34: =_xlfn.XLOOKUP(G31, 'Date master'!$E:$E,'Date master'!$F:$F, "") & " " & _xlfn.XLOOKUP(G31, 'Date master'!$E:$E, 'Date master'!$G:$G, "") | H34: =_xlfn.XLOOKUP(H31, 'Date master'!$E:$E,'Date master'!$F:$F, "") & " " & _xlfn.XLOOKUP(H31, 'Date master'!$E:$E, 'Date master'!$G:$G, "")

Sheet Commitments & Ownership Matrix
B2: Finance Team Recurrig Commitments & Deliverables
B5: Commitments | C5: Start | D5: Deadline | E5: Ad Hoc Deadlines | F5: Main Owner | G5: Audience | H5: Frecuency | I5: Category / Workstream | J5: Priority | K5: Status
B6: Sales close | C6: 1 | D6: 3 | F6: Manager | H6: Recurring | I6: Close & Accounting
B7: Revenue | C7: 1 | D7: 5 | F7: Senior Manager | H7: Exceptional | I7: Close & Accounting
B8: Payroll | C8: 1 | D8: 4 | F8: Payroll Analyst | H8: Recurring | I8: Close & Accounting
B9: Deferred Revenue | C9: 1 | D9: 6 | F9: Senior Analyst | H9: Recurring | I9: Close & Accounting
B10: Unbilled | C10: 4 | D10: 6 | F10: A/P A/R Analyst | H10: Recurring | I10: Close & Accounting
B11: AR Aging | C11: 2 | D11: 5 | F11: A/P A/R Analyst | H11: Recurring | I11: Close & Accounting
B12: Accrued Expenses | C12: 3 | D12: 5 | F12: Finance Manager | H12: Recurring | I12: Close & Accounting
B13: Prepaid Expenses | C13: 5 | D13: 6 | F13: Senior Finance Analyst | H13: Recurring | I13: Close & Accounting
B14: AP Aging | C14: 2 | D14: 5 | F14: A/P A/R Analyst | H14: Recurring | I14: Close & Accounting
B15: Credit Cards | C15: 1 | D15: 5 | F15: Junior Finance Analyst | H15: Recurring | I15: Close & Accounting
B16: Banking | C16: 1 | D16: 6 | F16: Finance Manager | H16: Recurring | I16: Close & Accounting
B17: Mid Close analysis | C17: 3 | D17: 7 | H17: Recurring | I17: Close & Accounting
B18: India Accounting | C18: 1 | D18: 6 | H18: Recurring | I18: Close & Accounting
B19: Intercompany transactions | C19: 6 | D19: 7 | H19: Recurring | I19: Close & Accounting
B20: Final Review | C20: 8 | D20: 8 | H20: Recurring | I20: Close & Accounting
B21: Financial Reporting Package Reporting | C21: 6 | D21: 9 | H21: Recurring | I21: Internal Reporting
B22: Financial Reporting Package Distribution | C22: 10 | D22: 10 | H22: Recurring | I22: Internal Reporting | J22: High
B23: Bank Reporting | C23: 20 | D23: 20 | H23: Recurring | I23: External Reporting | J23: Critical
B24: CEO Report | C24: 15 | D24: 15 | H24: Recurring | I24: Internal Reporting | J24: High
B25: R&D Report | C25: 13 | D25: 13 | H25: Recurring | I25: Internal Reporting
B26: Bank Report | C26: 11 | D26: 11 | H26: Recurring | I26: External Reporting
B27: Board Presentation | C27: 12 | D27: 12 | H27: Recurring | I27: Internal Reporting
B28: Example Special task 1 | C28: N/A | D28: N/A | E28: 45845 | H28: Exceptional | I28: Projects / Strategic Initiatives
B29: Example Special task 2 | C29: N/A | D29: N/A | E29: 7/232025 | H29: Exceptional | I29: Projects / Strategic Initiatives
B30: Example Special task 3 | C30: N/A | D30: N/A | E30: 45856 | H30: Exceptional | I30: Projects / Strategic Initiatives
B31: 2023 Audit Related example 1 | C31: N/A | D31: N/A | E31: 45852 | H31: Exceptional | I31: Compliance / Audit
B32: 2023 Audit Related example 2 | C32: N/A | D32: N/A | E32: 45860 | H32: Exceptional | I32: Compliance / Audit
B33: 2023 Audit Related example 3 | C33: N/A | D33: N/A | E33: 45866 | H33: Exceptional | I33: Compliance / Audit
B34: 2023 Audit Related example 4 | C34: N/A | D34: N/A | E34: 45840 | H34: Exceptional | I34: Compliance / Audit

Sheet Detailed Tasks
B2: Finance Team Commitments & Deliverables breakdown details
I4: Team Involved (alphabetical order)
B5: Commitments | C5: Detailed Task | D5: Start | E5: Deadline | F5: Ad Hoc Deadlines | G5: Main Owner | H5: Audience | I5: Team Member 1 | J5: Team Member 2 | K5: Team Member 3 | L5: Team Member 4 | M5: Team Member 5 | N5: Team Member 6 | O5: Team Member 7 | P5: Team Member 8 | Q5: Team Member 9 | R5: Frecuency | S5: Category / Workstream | T5: Priority | U5: Status
B6: Sales close | C6: =Table3[[#This Row],[Commitments]] -> Sales close | D6: 1 | E6: 3 | I6: No | J6: No | K6: No | L6: No | M6: No | N6: No | O6: No | P6: No | Q6: No | R6: Recurring | S6: Close & Accounting
B7: Revenue | C7: Existing MRR | D7: 1 | E7: 1 | I7: No | J7: No | K7: No | L7: No | M7: Yes | N7: Yes | O7: No | P7: No | Q7: No | R7: Recurring | S7: Close & Accounting
B8: Revenue | C8: New business | D8: 4 | E8: 4 | I8: Yes | J8: No | K8: No | L8: No | M8: Yes | N8: Yes | O8: No | P8: No | Q8: No | R8: Recurring
B9: Revenue | C9: Variable Fees | D9: 4 | E9: 4 | I9: No | J9: No | K9: No | L9: No | M9: Yes | N9: Yes | O9: No | P9: No | Q9: No | R9: Recurring
B10: Revenue | C10: Meeting to review monthly revenue | D10: 5 | E10: 5 | I10: Yes | J10: No | K10: No | L10: Yes | M10: Yes | N10: Yes | O10: No | P10: No | Q10: No | R10: Recurring
B11: Revenue | C11: Finalize | D11: 5 | E11: 5 | I11: Yes | J11: No | K11: No | L11: Yes | M11: Yes | N11: Yes | O11: No | P11: No | Q11: No | R11: Recurring
B12: Payroll | C12: Download Code payroll files | D12: 1 | E12: 1 | I12: Yes | J12: No | K12: No | L12: No | M12: No | N12: No | O12: No | P12: No | Q12: Yes | R12: Recurring | S12: Payroll | T12: High
B13: Payroll | C13: Book payroll | D13: 2 | E13: 2 | I13: No | J13: No | K13: No | L13: No | M13: No | N13: No | O13: No | P13: No | Q13: Yes | R13: Recurring | S13: Payroll | T13: High
B14: Payroll | C14: Reconciled payroll expense booked to payroll reports | D14: 3 | E14: 3 | I14: No | J14: No | K14: No | L14: No | M14: No | N14: No | O14: Yes | P14: No | Q14: Yes | R14: Recurring | S14: Payroll | T14: High
B15: Payroll | C15: Meeting to review payroll JE's through GL (P&L & BS) | D15: 4 | E15: 4 | I15: Yes | J15: No | K15: No | L15: Yes | M15: No | N15: No | O15: No | P15: No | Q15: Yes | R15: Recurring | S15: Payroll | T15: High
B16: Deferred Revenue | C16: Finalize | D16: 4 | E16: 4 | I16: Yes | J16: No | K16: No | L16: Yes | M16: Yes | N16: Yes | O16: No | P16: No | Q16: No | R16: Recurring
B17: Deferred Revenue | C17: Generate & distribute Deferred Revenue Detail Schedule, must tie to the BS by subsidiary | D17: 5 | E17: 5 | I17: No | J17: No | K17: No | L17: No | M17: Yes | N17: Yes | O17: No | P17: No | Q17: No | R17: Recurring
B18: Deferred Revenue | C18: Meeting to review Deferred Revenue Detail Schedule | D18: 6 | E18: 6 | I18: Yes | J18: No | K18: No | L18: Yes | M18: Yes | N18: Yes | O18: No | P18: No | Q18: No | R18: Recurring
B19: Unbilled | C19: New business | D19: 4 | E19: 4 | I19: Yes | J19: No | K19: No | L19: No | M19: Yes | N19: Yes | O19: No | P19: No | Q19: No | R19: Recurring
B20: Unbilled | C20: Variable Fees | D20: 4 | E20: 4 | I20: No | J20: No | K20: No | L20: No | M20: Yes | N20: Yes | O20: No | P20: No | Q20: No | R20: Recurring
B21: Unbilled | C21: Finalize | D21: 4 | E21: 4 | I21: Yes | J21: No | K21: No | L21: No | M21: Yes | N21: Yes | O21: No | P21: No | Q21: No | R21: Recurring
B22: Unbilled | C22: Generate & distribute Unbilled Revenue Detail Schedule, must tie to the BS by subsidiary | D22: 5 | E22: 5 | I22: No | J22: No | K22: No | L22: No | M22: Yes | N22: Yes | O22: No | P22: No | Q22: No | R22: Recurring
B23: Unbilled | C23: Meeting to review Unbilled Revenue Detail Schedule | D23: 6 | E23: 6 | I23: Yes | J23: No | K23: No | L23: Yes | M23: Yes | N23: Yes | O23: No | P23: No | Q23: No | R23: Recurring
B24: AR Aging | C24: Ensure all payments are posted in NS | D24: 2 | E24: 2 | I24: No | J24: No | K24: No | L24: No | M24: Yes | N24: Yes | O24: No | P24: No | Q24: No | R24: Recurring | S24: Cash & Treasury
B25: AR Aging | C25: Clean up aging to eliminate negative balances | D25: 3 | E25: 3 | I25: No | J25: No | K25: No | L25: No | M25: Yes | N25: Yes | O25: No | P25: No | Q25: No | R25: Recurring | S25: Cash & Treasury
B26: AR Aging | C26: Run & Save AR Aging in month end folder on One Drive | D26: 3 | E26: 3 | I26: No | J26: No | K26: No | L26: No | M26: Yes | N26: Yes | O26: No | P26: No | Q26: No | R26: Recurring | S26: Cash & Treasury
B27: AR Aging | C27: Meeting to review AR Aging | D27: 4 | E27: 5 | I27: Yes | J27: No | K27: No | L27: Yes | M27: Yes | N27: Yes | O27: No | P27: No | Q27: No | R27: Recurring | S27: Cash & Treasury
B28: AR Aging | C28: A/R Report by Delivery Function | D28: 4 | E28: 5 | I28: Yes | J28: No | K28: No | L28: Yes | M28: Yes | N28: Yes | O28: Yes | P28: No | Q28: No | R28: Recurring | S28: Cash & Treasury
B29: Accrued Expenses | C29: Maintain monthly accrued expenses | D29: 3 | E29: 3 | I29: No | J29: No | K29: No | L29: No | M29: No | N29: No | O29: No | P29: No | Q29: No | R29: Recurring
B30: Accrued Expenses | C30: Generate & distribute Accrued Expense Detail Schedule, must tie to the BS by subsidiary | D30: 4 | E30: 4 | I30: No | J30: No | K30: No | L30: No | M30: No | N30: No | O30: No | P30: No | Q30: No | R30: Recurring
B31: Accrued Expenses | C31: Meeting to review acrued expenses and month-over-months movements | D31: 5 | E31: 5 | I31: No | J31: No | K31: No | L31: No | M31: No | N31: No | O31: No | P31: No | Q31: No | R31: Recurring
B32: Prepaid Expenses | C32: Maintain monthly prepaid expenses | D32: 5 | E32: 5 | I32: No | J32: No | K32: No | L32: No | M32: No | N32: No | O32: No | P32: No | Q32: No | R32: Recurring
B33: Prepaid Expenses | C33: Generate & distribute Prepaid Expense Detail Schedule, must tie to the BS by subsidiary | D33: 6 | E33: 6 | I33: No | J33: No | K33: No | L33: No | M33: No | N33: No | O33: No | P33: No | Q33: No | R33: Recurring
B34: Prepaid Expenses | C34: Meeting to review Prepaid Expenses and month-over-months movements | D34: 6 | E34: 6 | I34: No | J34: No | K34: No | L34: No | M34: No | N34: No | O34: No | P34: No | Q34: No | R34: Recurring
B35: AP Aging | C35: Ensure all payments are posted in NS | D35: 2 | E35: 2 | I35: No | J35: No | K35: No | L35: No | M35: No | N35: No | O35: No | P35: No | Q35: No | R35: Recurring
B36: AP Aging | C36: Clean up aging to eliminate negative balances | D36: 3 | E36: 3 | I36: No | J36: No | K36: No | L36: No | M36: No | N36: No | O36: No | P36: No | Q36: No | R36: Recurring
B37: AP Aging | C37: Run & Save AP Aging in month end folder on Egnyte | D37: 3 | E37: 3 | I37: No | J37: No | K37: No | L37: No | M37: No | N37: No | O37: No | P37: No | Q37: No | R37: Recurring
B38: AP Aging | C38: Meeting to review AP Aging | D38: 5 | E38: 5 | I38: No | J38: No | K38: No | L38: No | M38: No | N38: No | O38: No | P38: No | Q38: No | R38: Recurring
B39: Credit Cards | C39: Download credit reports | D39: 1 | E39: 1 | I39: No | J39: No | K39: No | L39: No | M39: No | N39: No | O39: No | P39: No | Q39: No | R39: Recurring
B40: Credit Cards | C40: Reconcile & process | D40: 5 | E40: 5 | I40: No | J40: No | K40: No | L40: No | M40: No | N40: No | O40: No | P40: No | Q40: No | R40: Recurring
... B49: Financial Reporting Package Final Review | C49: Final review and adjusting entries | D49: 8 | E49: 8 | I49: No | J49: No | K49: No | L49: No | M49: No | N49: No | O49: No | P49: No | Q49: No | R49: Recurring
B50: Financial Reporting Package Reporting | C50: Prep of Financial Reporting Package & Work Copy | D50: 6 | E50: 9 | H50: Director / cfo | I50: No | J50: No | K50: No | L50: No | M50: No | N50: No | O50: No | P50: No | Q50: No | R50: Recurring
...

Sheet Schedules>>

Sheet Date master
B1: Year | C1: Month | D1: Weekday | E1: Date | F1: US Holiday | G1: India Holiday | H1: Holiday? | I1: Finance day
B2: =YEAR(E2) -> 2025 | C2: =TEXT(E2,"mmmm") -> July | D2: =TEXT(E2,"dddd") -> Tuesday | E2: 45839 | H2: =IF(OR(Table1[[#This Row],[US Holiday]]<>"", Table1[[#This Row],[India Holiday]]<>""), "Yes", "No") -> No | I2: 1
B3: =YEAR(E3) -> 2025 | C3: =TEXT(E3,"mmmm") -> July | D3: =TEXT(E3,"dddd") -> Wednesday | E3: 45840 | H3: =IF(OR(Table1[[#This Row],[US Holiday]]<>"", Table1[[#This Row],[India Holiday]]<>""), "Yes", "No") -> No | I3: =IF( AND( WORKDAY(E3-1,1)=E3, _xlfn.CONCAT(F3:G3)="" ), _xlfn.MAXIFS(I$2:I2,C$2:C2,C3,B$2:B2,B3)+1, "" ) -> 2
B4: =YEAR(E4) -> 2025 | C4: =TEXT(E4,"mmmm") -> July | D4: =TEXT(E4,"dddd") -> Thursday | E4: 45841 | H4: =IF(OR(Table1[[#This Row],[US Holiday]]<>"", Table1[[#This Row],[India Holiday]]<>""), "Yes", "No") -> No | I4: =IF( AND( WORKDAY(E4-1,1)=E4, _xlfn.CONCAT(F4:G4)="" ), _xlfn.MAXIFS(I$2:I3,C$2:C3,C4,B$2:B3,B4)+1, "" ) -> 3
B5: =YEAR(E5) -> 2025 | C5: =TEXT(E5,"mmmm") -> July | D5: =TEXT(E5,"dddd") -> Friday | E5: 45842 | F5: US Independence Day | H5: =IF(OR(Table1[[#This Row],[US Holiday]]<>"", Table1[[#This Row],[India Holiday]]<>""), "Yes", "No") -> Yes | I5: =IF( AND( WORKDAY(E5-1,1)=E5, _xlfn.CONCAT(F5:G5)="" ), _xlfn.MAXIFS(I$2:I4,C$2:C4,C5,B$2:B4,B5)+1, "" )
B6: =YEAR(E6) -> 2025 | C6: =TEXT(E6,"mmmm") -> July | D6: =TEXT(E6,"dddd") -> Saturday | E6: 45843 | H6: =IF(OR(Table1[[#This Row],[US Holiday]]<>"", Table1[[#This Row],[India Holiday]]<>""), "Yes", "No") -> No | I6: =IF( AND( WORKDAY(E6-1,1)=E6, _xlfn.CONCAT(F6:G6)="" ), _xlfn.MAXIFS(I$2:I5,C$2:C5,C6,B$2:B5,B6)+1, "" )
B7: =YEAR(E7) -> 2025 | C7: =TEXT(E7,"mmmm") -> July | D7: =TEXT(E7,"dddd") -> Sunday | E7: 45844 | H7: =IF(OR(Table1[[#This Row],[US Holiday]]<>"", Table1[[#This Row],[India Holiday]]<>""), "Yes", "No") -> No | I7: =IF( AND( WORKDAY(E7-1,1)=E7, _xlfn.CONCAT(F7:G7)="" ), _xlfn.MAXIFS(I$2:I6,C$2:C6,C7,B$2:B6,B7)+1, "" )
B8: =YEAR(E8) -> 2025 | C8: =TEXT(E8,"mmmm") -> July | D8: =TEXT(E8,"dddd") -> Monday | E8: 45845 | H8: =IF(OR(Table1[[#This Row],[US Holiday]]<>"", Table1[[#This Row],[India Holiday]]<>""), "Yes", "No") -> No | I8: =IF( AND( WORKDAY(E8-1,1)=E8, _xlfn.CONCAT(F8:G8)="" ), _xlfn.MAXIFS(I$2:I7,C$2:C7,C8,B$2:B7,B8)+1, "" ) -> 4
B9: =YEAR(E9) -> 2025 | C9: =TEXT(E9,"mmmm") -> July | D9: =TEXT(E9,"dddd") -> Tuesday | E9: 45846 | H9: =IF(OR(Table1[[#This Row],[US Holiday]]<>"", Table1[[#This Row],[India Holiday]]<>""), "Yes", "No") -> No | I9: =IF( AND( WORKDAY(E9-1,1)=E9, _xlfn.CONCAT(F9:G9)="" ), _xlfn.MAXIFS(I$2:I8,C$2:C8,C9,B$2:B8,B9)+1, "" ) -> 5
B10: =YEAR(E10) -> 2025 | C10: =TEXT(E10,"mmmm") -> July | D10: =TEXT(E10,"dddd") -> Wednesday | E10: 45847 | H10: =IF(OR(Table1[[#This Row],[US Holiday]]<>"", Table1[[#This Row],[India Holiday]]<>""), "Yes", "No") -> No | I10: =IF( AND( WORKDAY(E10-1,1)=E10, _xlfn.CONCAT(F10:G10)="" ), _xlfn.MAXIFS(I$2:I9,C$2:C9,C10,B$2:B9,B10)+1, "" ) -> 6
B11: =YEAR(E11) -> 2025 | C11: =TEXT(E11,"mmmm") -> July | D11: =TEXT(E11,"dddd") -> Thursday | E11: 45848 | H11: =IF(OR(Table1[[#This Row],[US Holiday]]<>"", Table1[[#This Row],[India Holiday]]<>""), "Yes", "No") -> No | I11: =IF( AND( WORKDAY(E11-1,1)=E11, _xlfn.CONCAT(F11:G11)="" ), _xlfn.MAXIFS(I$2:I10,C$2:C10,C11,B$2:B10,B11)+1, "" ) -> 7
B12: =YEAR(E12) -> 2025 | C12: =TEXT(E12,"mmmm") -> July | D12: =TEXT(E12,"dddd") -> Friday | E12: 45849 | H12: =IF(OR(Table1[[#This Row],[US Holiday]]<>"", Table1[[#This Row],[India Holiday]]<>""), "Yes", "No") -> No | I12: =IF( AND( WORKDAY(E12-1,1)=E12, _xlfn.CONCAT(F12:G12)="" ), _xlfn.MAXIFS(I$2:I11,C$2:C11,C12,B$2:B11,B12)+1, "" ) -> 8
B13: =YEAR(E13) -> 2025 | C13: =TEXT(E13,"mmmm") -> July | D13: =TEXT(E13,"dddd") -> Saturday | E13: 45850 | H13: =IF(OR(Table1[[#This Row],[US Holiday]]<>"", Table1[[#This Row],[India Holiday]]<>""), "Yes", "No") -> No | I13: =IF( AND( WORKDAY(E13-1,1)=E13, _xlfn.CONCAT(F13:G13)="" ), _xlfn.MAXIFS(I$2:I12,C$2:C12,C13,B$2:B12,B13)+1, "" )
B14: =YEAR(E14) -> 2025 | C14: =TEXT(E14,"mmmm") -> July | D14: =TEXT(E14,"dddd") -> Sunday | E14: 45851 | H14: =IF(OR(Table1[[#This Row],[US Holiday]]<>"", Table1[[#This Row],[India Holiday]]<>""), "Yes", "No") -> No | I14: =IF( AND( WORKDAY(E14-1,1)=E14, _xlfn.CONCAT(F14:G14)="" ), _xlfn.MAXIFS(I$2:I13,C$2:C13,C14,B$2:B13,B14)+1, "" )
B15: =YEAR(E15) -> 2025 | C15: =TEXT(E15,"mmmm") -> July | D15: =TEXT(E15,"dddd") -> Monday | E15: 45852 | H15: =IF(OR(Table1[[#This Row],[US Holiday]]<>"", Table1[[#This Row],[India Holiday]]<>""), "Yes", "No") -> No | I15: =IF( AND( WORKDAY(E15-1,1)=E15, _xlfn.CONCAT(F15:G15)="" ), _xlfn.MAXIFS(I$2:I14,C$2:C14,C15,B$2:B14,B15)+1, "" ) -> 9
B16: =YEAR(E16) -> 2025 | C16: =TEXT(E16,"mmmm") -> July | D16: =TEXT(E16,"dddd") -> Tuesday | E16: 45853 | H16: =IF(OR(Table1[[#This Row],[US Holiday]]<>"", Table1[[#This Row],[India Holiday]]<>""), "Yes", "No") -> No | I16: =IF( AND( WORKDAY(E16-1,1)=E16, _xlfn.CONCAT(F16:G16)="" ), _xlfn.MAXIFS(I$2:I15,C$2:C15,C16,B$2:B15,B16)+1, "" ) -> 10
B17: =YEAR(E17) -> 2025 | C17: =TEXT(E17,"mmmm") -> July | D17: =TEXT(E17,"dddd") -> Wednesday | E17: 45854 | H17: =IF(OR(Table1[[#This Row],[US Holiday]]<>"", Table1[[#This Row],[India Holiday]]<>""), "Yes", "No") -> No | I17: =IF( AND( WORKDAY(E17-1,1)=E17, _xlfn.CONCAT(F17:G17)="" ), _xlfn.MAXIFS(I$2:I16,C$2:C16,C17,B$2:B16,B17)+1, "" ) -> 11
... B46: =YEAR(E46) -> 2025 | C46: =TEXT(E46,"mmmm") -> August | D46: =TEXT(E46,"dddd") -> Thursday | E46: 45883 | H46: =IF(OR(Table1[[#This Row],[US Holiday]]<>"", Table1[[#This Row],[India Holiday]]<>""), "Yes", "No") -> No | I46: =IF( AND( WORKDAY(E46-1,1)=E46, _xlfn.CONCAT(F46:G46)="" ), _xlfn.MAXIFS(I$2:I45,C$2:C45,C46,B$2:B45,B46)+1, "" ) -> 10
B47: =YEAR(E47) -> 2025 | C47: =TEXT(E47,"mmmm") -> August | D47: =TEXT(E47,"dddd") -> Friday | E47: 45884 | G47: India Independence Day | H47: =IF(OR(Table1[[#This Row],[US Holiday]]<>"", Table1[[#This Row],[India Holiday]]<>""), "Yes", "No") -> Yes | I47: =IF( AND( WORKDAY(E47-1,1)=E47, _xlfn.CONCAT(F47:G47)="" ), _xlfn.MAXIFS(I$2:I46,C$2:C46,C47,B$2:B46,B47)+1, "" )
B48: =YEAR(E48) -> 2025 | C48: =TEXT(E48,"mmmm") -> August | D48: =TEXT(E48,"dddd") -> Saturday | E48: 45885 | H48: =IF(OR(Table1[[#This Row],[US Holiday]]<>"", Table1[[#This Row],[India Holiday]]<>""), "Yes", "No") -> No | I48: =IF( AND( WORKDAY(E48-1,1)=E48, _xlfn.CONCAT(F48:G48)="" ), _xlfn.MAXIFS(I$2:I47,C$2:C47,C48,B$2:B47,B48)+1, "" )
B49: =YEAR(E49) -> 2025 | C49: =TEXT(E49,"mmmm") -> August | D49: =TEXT(E49,"dddd") -> Sunday | E49: 45886 | H49: =IF(OR(Table1[[#This Row],[US Holiday]]<>"", Table1[[#This Row],[India Holiday]]<>""), "Yes", "No") -> No | I49: =IF( AND( WORKDAY(E49-1,1)=E49, _xlfn.CONCAT(F49:G49)="" ), _xlfn.MAXIFS(I$2:I48,C$2:C48,C49,B$2:B48,B49)+1, "" )
B50: =YEAR(E50) -> 2025 | C50: =TEXT(E50,"mmmm") -> August | D50: =TEXT(E50,"dddd") -> Monday | E50: 45887 | H50: =IF(OR(Table1[[#This Row],[US Holiday]]<>"", Table1[[#This Row],[India Holiday]]<>""), "Yes", "No") -> No | I50: =IF( AND( WORKDAY(E50-1,1)=E50, _xlfn.CONCAT(F50:G50)="" ), _xlfn.MAXIFS(I$2:I49,C$2:C49,C50,B$2:B49,B50)+1, "" ) -> 11
B51: =YEAR(E51) -> 2025 | C51: =TEXT(E51,"mmmm") -> August | D51: =TEXT(E51,"dddd") -> Tuesday | E51: 45888 | H51: =IF(OR(Table1[[#This Row],[US Holiday]]<>"", Table1[[#This Row],[India Holiday]]<>""), "Yes", "No") -> No | I51: =IF( AND( WORKDAY(E51-1,1)=E51, _xlfn.CONCAT(F51:G51)="" ), _xlfn.MAXIFS(I$2:I50,C$2:C50,C51,B$2:B50,B51)+1, "" ) -> 12
B52: =YEAR(E52) -> 2025 | C52: =TEXT(E52,"mmmm") -> August | D52: =TEXT(E52,"dddd") -> Wednesday | E52: 45889 | H52: =IF(OR(Table1[[#This Row],[US Holiday]]<>"", Table1[[#This Row],[India Holiday]]<>""), "Yes", "No") -> No | I52: =IF( AND( WORKDAY(E52-1,1)=E52, _xlfn.CONCAT(F52:G52)="" ), _xlfn.MAXIFS(I$2:I51,C$2:C51,C52,B$2:B51,B52)+1, "" ) -> 13
B53: =YEAR(E53) -> 2025 | C53: =TEXT(E53,"mmmm") -> August | D53: =TEXT(E53,"dddd") -> Thursday | E53: 45890 | H53: =IF(OR(Table1[[#This Row],[US Holiday]]<>"", Table1[[#This Row],[India Holiday]]<>""), "Yes", "No") -> No | I53: =IF( AND( WORKDAY(E53-1,1)=E53, _xlfn.CONCAT(F53:G53)="" ), _xlfn.MAXIFS(I$2:I52,C$2:C52,C53,B$2:B52,B53)+1, "" ) -> 14
B54: =YEAR(E54) -> 2025 | C54: =TEXT(E54,"mmmm") -> August | D54: =TEXT(E54,"dddd") -> Friday | E54: 45891 | H54: =IF(OR(Table1[[#This Row],[US Holiday]]<>"", Table1[[#This Row],[India Holiday]]<>""), "Yes", "No") -> No | I54: =IF( AND( WORKDAY(E54-1,1)=E54, _xlfn.CONCAT(F54:G54)="" ), _xlfn.MAXIFS(I$2:I53,C$2:C53,C54,B$2:B53,B54)+1, "" ) -> 15
B55: =YEAR(E55) -> 2025 | C55: =TEXT(E55,"mmmm") -> August | D55: =TEXT(E55,"dddd") -> Saturday | E55: 45892 | H55: =IF(OR(Table1[[#This Row],[US Holiday]]<>"", Table1[[#This Row],[India Holiday]]<>""), "Yes", "No") -> No | I55: =IF( AND( WORKDAY(E55-1,1)=E55, _xlfn.CONCAT(F55:G55)="" ), _xlfn.MAXIFS(I$2:I54,C$2:C54,C55,B$2:B54,B55)+1, "" )
B56: =YEAR(E56) -> 2025 | C56: =TEXT(E56,"mmmm") -> August | D56: =TEXT(E56,"dddd") -> Sunday | E56: 45893 | H56: =IF(OR(Table1[[#This Row],[US Holiday]]<>"", Table1[[#This Row],[India Holiday]]<>""), "Yes", "No") -> No | I56: =IF( AND( WORKDAY(E56-1,1)=E56, _xlfn.CONCAT(F56:G56)="" ), _xlfn.MAXIFS(I$2:I55,C$2:C55,C56,B$2:B55,B56)+1, "" )
B57: =YEAR(E57) -> 2025 | C57: =TEXT(E57,"mmmm") -> August | D57: =TEXT(E57,"dddd") -> Monday | E57: 45894 | H57: =IF(OR(Table1[[#This Row],[US Holiday]]<>"", Table1[[#This Row],[India Holiday]]<>""), "Yes", "No") -> No | I57: =IF( AND( WORKDAY(E57-1,1)=E57, _xlfn.CONCAT(F57:G57)="" ), _xlfn.MAXIFS(I$2:I56,C$2:C56,C57,B$2:B56,B57)+1, "" ) -> 16
B58: =YEAR(E58) -> 2025 | C58: =TEXT(E58,"mmmm") -> August | D58: =TEXT(E58,"dddd") -> Tuesday | E58: 45895 | H58: =IF(OR(Table1[[#This Row],[US Holiday]]<>"", Table1[[#This Row],[India Holiday]]<>""), "Yes", "No") -> No | I58: =IF( AND( WORKDAY(E58-1,1)=E58, _xlfn.CONCAT(F58:G58)="" ), _xlfn.MAXIFS(I$2:I57,C$2:C57,C58,B$2:B57,B58)+1, "" ) -> 17
B59: =YEAR(E59) -> 2025 | C59: =TEXT(E59,"mmmm") -> August | D59: =TEXT(E59,"dddd") -> Wednesday | E59: 45896 | H59: =IF(OR(Table1[[#This Row],[US Holiday]]<>"", Table1[[#This Row],[India Holiday]]<>""), "Yes", "No") -> No | I59: =IF( AND( WORKDAY(E59-1,1)=E59, _xlfn.CONCAT(F59:G59)="" ), _xlfn.MAXIFS(I$2:I58,C$2:C58,C59,B$2:B58,B59)+1, "" ) -> 18
... B63: =YEAR(E63) -> 2025 | C63: =TEXT(E63,"mmmm") -> August | D63: =TEXT(E63,"dddd") -> Sunday | E63: 45900 | H63: =IF(OR(Table1[[#This Row],[US Holiday]]<>"", Table1[[#This Row],[India Holiday]]<>""), "Yes", "No") -> No | I63: =IF( AND( WORKDAY(E63-1,1)=E63, _xlfn.CONCAT(F63:G63)="" ), _xlfn.MAXIFS(I$2:I62,C$2:C62,C63,B$2:B62,B63)+1, "" )
B64: =YEAR(E64) -> 2025 | C64: =TEXT(E64,"mmmm") -> September | D64: =TEXT(E64,"dddd") -> Monday | E64: 45901 | F64: Labor Day | H64: =IF(OR(Table1[[#This Row],[US Holiday]]<>"", Table1[[#This Row],[India Holiday]]<>""), "Yes", "No") -> Yes | I64: =IF( AND( WORKDAY(E64-1,1)=E64, _xlfn.CONCAT(F64:G64)="" ), _xlfn.MAXIFS(I$2:I63,C$2:C63,C64,B$2:B63,B64)+1, "" )
B65: =YEAR(E65) -> 2025 | C65: =TEXT(E65,"mmmm") -> September | D65: =TEXT(E65,"dddd") -> Tuesday | E65: 45902 | H65: =IF(OR(Table1[[#This Row],[US Holiday]]<>"", Table1[[#This Row],[India Holiday]]<>""), "Yes", "No") -> No | I65: =IF( AND( WORKDAY(E65-1,1)=E65, _xlfn.CONCAT(F65:G65)="" ), _xlfn.MAXIFS(I$2:I64,C$2:C64,C65,B$2:B64,B65)+1, "" ) -> 1
B66: =YEAR(E66) -> 2025 | C66: =TEXT(E66,"mmmm") -> September | D66: =TEXT(E66,"dddd") -> Wednesday | E66: 45903 | H66: =IF(OR(Table1[[#This Row],[US Holiday]]<>"", Table1[[#This Row],[India Holiday]]<>""), "Yes", "No") -> No | I66: =IF( AND( WORKDAY(E66-1,1)=E66, _xlfn.CONCAT(F66:G66)="" ), _xlfn.MAXIFS(I$2:I65,C$2:C65,C66,B$2:B65,B66)+1, "" ) -> 2
B67: =YEAR(E67) -> 2025 | C67: =TEXT(E67,"mmmm") -> September | D67: =TEXT(E67,"dddd") -> Thursday | E67: 45904 | H67: =IF(OR(Table1[[#This Row],[US Holiday]]<>"", Table1[[#This Row],[India Holiday]]<>""), "Yes", "No") -> No | I67: =IF( AND( WORKDAY(E67-1,1)=E67, _xlfn.CONCAT(F67:G67)="" ), _xlfn.MAXIFS(I$2:I66,C$2:C66,C67,B$2:B66,B67)+1, "" ) -> 3
B68: =YEAR(E68) -> 2025 | C68: =TEXT(E68,"mmmm") -> September | D68: =TEXT(E68,"dddd") -> Friday | E68: 45905 | H68: =IF(OR(Table1[[#This Row],[US Holiday]]<>"", Table1[[#This Row],[India Holiday]]<>""), "Yes", "No") -> No | I68: =IF( AND( WORKDAY(E68-1,1)=E68, _xlfn.CONCAT(F68:G68)="" ), _xlfn.MAXIFS(I$2:I67,C$2:C67,C68,B$2:B67,B68)+1, "" ) -> 4
