Workbook

Sheet Index
B2: Index
B4: Forecast
A5: ▪ | B5: Forecast Assumptions
A6: ▪ | B6: Forecast Sep - Nov 2025
A8: ▪ | B8: Dashboard
A10: ▪ | B10: Metrics & Statistics
A12: ▪ | B12: Plan
A14: ▪ | B14: Data Source
A16: ▪ | B16: Assignment Approach

Sheet Forecast Assumptions
B2: Assumptions – Pipeline-Driven Forecast Model
B3: Quarter: Sep–Nov 2025
B5: Revenue - Type
B6: ▪ | C6: All opportunities treated as Recurring Revenue (no projects).
B7: ▪ | C7: Based on Lead Source categories (Inbound Marketing, Outbound SDR, Partner, Referral, Webinar), all opportunities classified as New Business (no renewals).
B9: Revenue Phasing
B10: ▪ | C10: Contracts from current pipeline opportunities begin on the 1st of the month following the Close Date.
B11: ▪ | C11: Opportunities closing Sep 2025 or later: revenue starts the following month (e.g., Sep 25 close → Oct 25 start). (Scenario 1 only)
B12: ▪ | C12: Opportunities closing before Sep 2025: shifted to next quarter, phased by Sales Stage (Scenario 1 only):
C13: Negotiation/Review → Sep revenue
C14: Value Proposition → Oct revenue
C15: Earlier stages → Nov revenue
B17: New Opportunities Placeholder
B18: ▪ | C18: Since data only covers opportunities created through Aug 2025, a placeholder is included for new leads created after Sep 1, 2025.
B19: ▪ | C19: Revenue estimated using:
C20: Avg. monthly opportunities created (Apr–Aug 2025)
C21: Moving $ARR average of Closed Won opportunities (Apr–Aug 2025)
C22: Win rate from Closed Won opportunities (Apr–Aug 2025)
C23: Modifiable parameter: Avg. Sales Cycle Days from closed deals (drives monthly phasing).
B25: Other Revenue changes
B26: ▪ | C26: Churn, contraction, and expansion not included.
B28: Sales Team
B29: ▪ | C29: Team structure unchanged during forecast period (no new hires or exits).
B30: ▪ | C30: All team members are experienced; no onboarding ramp assumed.
B32: Scenarios
B33: #1 | C33: Base Case: Salesforce probability-weighted ARR + New Opportunities created after Sep 1, 2025.
B34: #2 | C34: Adjusted Case: Based on Scenario 1, with probabilities modifiable for conservative/optimistic views.
B35: ▪ | C35: Metrics/Dashboard development based on Scenario 1.
B37: Plan Reference
B38: ▪ | C38: Plan incorporates ARR amounts, phasing, win rate, and average sales cycle days.

Sheet Forecast Sep-Nov 2025
B2: Revenue Forecast
B3: Period: Nov - Sep 2025
J5: Current Month - ARR start date
B6: Scenario 1: Considering only Salesforce Probability on ARR $ | J6: 45901 | K6: Used for phasing opportunities with Close Dates before September, these are shifted to the next quarter (Sep–Nov).
C7: 45901 | D7: 45931 | E7: 45962 | F7: 45992 | G7: Total ARR
B8: Target ARR - Plan | C8: ='Plan '!$C$10 -> 425250 | D8: ='Plan '!$C$11 -> 486000 | E8: ='Plan '!$C$12 -> 303750 | J8: Next Quarter Target ARR (Plan) | L8: Current Reference
J9: =L9 -> 1215000 | L9: ='Plan '!B7 -> 1215000
B10: Forecast ARR | C10: =SUMIFS(Data!$N:$N, Data!$L:$L, "Open", Data!$R:$R, C$7) -> 899400 | D10: =SUMIFS(Data!$N:$N, Data!$L:$L, "Open", Data!$R:$R, D$7) -> 489500 | E10: =SUMIFS(Data!$N:$N, Data!$L:$L, "Open", Data!$R:$R, E$7) -> 252100 | G10: =SUM(C10:E10) -> 1641000
B11: New opps placeholder | C11: =SUMIFS( $C$39:$Z$39, $C$38:$Z$38, ">=" & EOMONTH(C$7,-1)+1, $C$38:$Z$38, "<=" & EOMONTH(C$7,0) ) -> 0 | D11: =SUMIFS( $C$39:$Z$39, $C$38:$Z$38, ">=" & EOMONTH(D$7,-1)+1, $C$38:$Z$38, "<=" & EOMONTH(D$7,0) ) -> 0 | E11: =SUMIFS( $C$39:$Z$39, $C$38:$Z$38, ">=" & EOMONTH(E$7,-1)+1, $C$38:$Z$38, "<=" & EOMONTH(E$7,0) ) -> 142263.33 | F11: =SUMIFS( $C$39:$Z$39, $C$38:$Z$38, ">=" & EOMONTH(F$7,-1)+1, $C$38:$Z$38, "<=" & EOMONTH(F$7,0) ) -> 162586.67 | G11: =SUM(C11:E11) -> 142263.33 | J11: Expected ARR – Current Open Opportunities (Salesforce)
B12: TOTAL ARR Fcst | C12: =SUM(C9:C11) -> 899400 | D12: =SUM(D9:D11) -> 489500 | E12: =SUM(E9:E11) -> 394363.33 | F12: =SUM(F9:F11) -> 162586.67 | G12: =SUM(G9:G11) -> 1783263.3 | H12: =IF(G12>$J$9,1,0) -> 1 | J12: 1
B14: Scenario 2: Applying adjusted probabilities to Scenario 1 ARR $
C15: 45901 | D15: 45931 | E15: 45962 | F15: 45992 | G15: Total ARR
B16: Target - Plan | C16: ='Plan '!$C$10 -> 425250 | D16: ='Plan '!$C$11 -> 486000 | E16: ='Plan '!$C$12 -> 303750
C17: 0.4 | D17: 0.4 | E17: 0.2 | G17: =SUM(C17:F17) -> 1 | H17: =IF(SUM(C17:E17)=1,"","⚠ Total must equal 100%")
B18: Forecast ARR | C18: =C17*$G$18 -> 656400 | D18: =D17*$G$18 -> 656400 | E18: =E17*$G$18 -> 328200 | G18: =SUMIF(Data!L:L,"Open",Data!N:N)*J12 -> 1641000
B19: New opps placeholder | C19: =SUMIFS( $C$39:$Z$39, $C$38:$Z$38, ">=" & EOMONTH(C$7,-1)+1, $C$38:$Z$38, "<=" & EOMONTH(C$7,0) ) -> 0 | D19: =SUMIFS( $C$39:$Z$39, $C$38:$Z$38, ">=" & EOMONTH(D$7,-1)+1, $C$38:$Z$38, "<=" & EOMONTH(D$7,0) ) -> 0 | E19: =SUMIFS( $C$39:$Z$39, $C$38:$Z$38, ">=" & EOMONTH(E$7,-1)+1, $C$38:$Z$38, "<=" & EOMONTH(E$7,0) ) -> 142263.33 | F19: =SUMIFS( $C$39:$Z$39, $C$38:$Z$38, ">=" & EOMONTH(F$7,-1)+1, $C$38:$Z$38, "<=" & EOMONTH(F$7,0) ) -> 162586.67 | G19: =SUM(C19:E19) -> 142263.33
B20: TOTAL ARR Fcst | C20: =SUM(C17:C19) -> 656400.4 | D20: =SUM(D17:D19) -> 656400.4 | E20: =SUM(E17:E19) -> 470463.53 | F20: =SUM(F17:F19) -> 162586.67 | G20: =SUM(G18:G19) -> 1783263.3 | H20: =IF(G20>$J$9,1,0) -> 1
B24: Revenue from "New Opportunities" Placeholder
B25: Total average $ARR Opps (closed deals) | C25: ='Metrics & Statistics'!$B$19 -> 62214.286 | E25: Current reference
B26: Sales Cycle Days Average | C26: =E26 -> 54.846154 | E26: ='Metrics & Statistics'!$B$25 -> 54.846154 | F26: Days
B27: Average opps created per month | C27: =E27 -> 9.8 | E27: ='Metrics & Statistics'!$B$8 -> 9.8
B28: Win Rate | C28: =E28 -> 0.66666667 | E28: ='Metrics & Statistics'!$C$29 -> 0.66666667
C31: 45901 | D31: 45931 | E31: 45962 | F31: 45992 | G31: Total
C32: 0.35 | D32: 0.4 | E32: 0.25 | G32: =SUM(C32:F32) -> 1 | H32: =IF(SUM(C32:E32)=1,"","⚠ Total must equal 100%")
B33: Number of Opps to add | C33: =C32*$G$33 -> 10.29 | D33: =D32*$G$33 -> 11.76 | E33: =E32*$G$33 -> 7.35 | G33: =C27*3 -> 29.4
C34: 45901 | D34: 45931 | E34: 45962 | F34: 45992
B35: Total Revenue addition to the Pipeline | C35: =C32*$G$35 -> 142263.33 | D35: =D32*$G$35 -> 162586.67 | E35: =E32*$G$35 -> 101616.67 | F35: =F32*$F$15 -> 0 | G35: =C25*C27*C28 -> 406466.67
B37: Opportunity Closing Date | C37: =C31+$C$26 -> 45955.846 | D37: =D31+$C$26 -> 45985.846 | E37: =E31+$C$26 -> 46016.846 | F37: =F31+$C$26 -> 46046.846
B38: Revenue Phasing | C38: =EOMONTH(C37,0)+1 -> 45962 | D38: =EOMONTH(D37,0)+1 -> 45992 | E38: =EOMONTH(E37,0)+1 -> 46023 | F38: =EOMONTH(F37,0)+1 -> 46054
B39: Total ARR from New Opps - 2025 | C39: =C35 -> 142263.33 | D39: =D35 -> 162586.67 | E39: =E35 -> 101616.67 | F39: =F35 -> 0 | G39: =SUMIFS(C39:F39, C39:F39, ">=1/1/2025", C38:F38, "<=12/31/2025") -> 304850
B40: Pushed to 2026 | G40: =G35-G39 -> 101616.67

Sheet Dashboard
F10: Pipeline Stages | G10: % ARR | H10: Current $ ARR | I10: Average Days since start date
F11: {='Metrics & Statistics'!E5:E9} -> Prospecting | G11: {='Metrics & Statistics'!G5:G9} -> 0.16313858 | H11: {='Metrics & Statistics'!F5:F9} -> 578000 | I11: {='Metrics & Statistics'!H5:H9} -> 104.8
F12: Qualification | G12: 0.12983347 | H12: 460000 | I12: 106.2
F13: Needs Analysis | G13: 0.27152131 | H13: 962000 | I13: 86.333333
F14: Value Proposition | G14: 0.18063788 | H14: 640000 | I14: 118
F15: Negotiation/Review | G15: 0.25486876 | H15: 903000 | I15: 112.66667
F17: {='Metrics & Statistics'!A41:A44} -> Sales Rep | G17: {='Metrics & Statistics'!D41:D44} -> Win Rate | H17: {='Metrics & Statistics'!G41:G44} -> Current open ARR | I17: {='Metrics & Statistics'!L41:L44} -> Average Days since Opp start date
F18: Bob Johnson | G18: 0.625 | H18: 1010000 | I18: 114.4375
F19: Charlie Brown | G19: 0.6 | H19: 1510000 | I19: 109.0625
F20: Lucy Smith | G20: 0.75 | H20: 1023000 | I20: 112.58824

Sheet Metrics & Statistics
A1: Statistics Summary - Sales Metrics
A2: General Metrics
A3: Total Pipeline ARR $ | B3: =SUMIF(Data!L:L,"Open",Data!B:B) -> 3543000 | E3: Pipeline - ARR by Stage | F3: $ ARR by Stage | G3: % ARR | H3: Average Days since start date
E4: Stage | H4: As of Aug 31st
A5: Target MRR next quarter | B5: ='Plan '!B7 -> 1215000 | C5: Assumption from Plan | E5: Prospecting | F5: =SUMIFS( Pipeline[Annual Recurring Revenue (ARR)], Pipeline[Stage], E5, Pipeline[General Stage], "Open" ) -> 578000 | G5: {=_xlfn.ANCHORARRAY(F5)/$F$11} -> 0.16313858 | H5: =AVERAGEIFS(Pipeline[Days past since Opp creation], Pipeline[Stage], E5) -> 104.8
A6: Pipeline Coverage | B6: =B3/B5 -> 2.9160494 | E6: Qualification | F6: =SUMIFS( Pipeline[Annual Recurring Revenue (ARR)], Pipeline[Stage], E6, Pipeline[General Stage], "Open" ) -> 460000 | G6: {=_xlfn.ANCHORARRAY(F6)/$F$11} -> 0.12983347 | H6: =AVERAGEIFS(Pipeline[Days past since Opp creation], Pipeline[Stage], E6) -> 106.2
E7: Needs Analysis | F7: =SUMIFS( Pipeline[Annual Recurring Revenue (ARR)], Pipeline[Stage], E7, Pipeline[General Stage], "Open" ) -> 962000 | G7: {=_xlfn.ANCHORARRAY(F7)/$F$11} -> 0.27152131 | H7: =AVERAGEIFS(Pipeline[Days past since Opp creation], Pipeline[Stage], E7) -> 86.333333
A8: # of Average Opps Created per month | B8: =AVERAGE(B11:B15) -> 9.8 | E8: Value Proposition | F8: =SUMIFS( Pipeline[Annual Recurring Revenue (ARR)], Pipeline[Stage], E8, Pipeline[General Stage], "Open" ) -> 640000 | G8: {=_xlfn.ANCHORARRAY(F8)/$F$11} -> 0.18063788 | H8: =AVERAGEIFS(Pipeline[Days past since Opp creation], Pipeline[Stage], E8) -> 118
E9: Negotiation/Review | F9: =SUMIFS( Pipeline[Annual Recurring Revenue (ARR)], Pipeline[Stage], E9, Pipeline[General Stage], "Open" ) -> 903000 | G9: {=_xlfn.ANCHORARRAY(F9)/$F$11} -> 0.25486876 | H9: =AVERAGEIFS(Pipeline[Days past since Opp creation], Pipeline[Stage], E9) -> 112.66667
A10: Month | B10: # Opps created | C10: ARR Closed
A11: 45748 | B11: =COUNTIFS( Pipeline[Opportunity Create Date], ">=" & A11, Pipeline[Opportunity Create Date], "<" & EDATE(A11,1) ) -> 18 | C11: =SUMIFS( Pipeline[Annual Recurring Revenue (ARR)], Pipeline[Close Date], ">=" & A11, Pipeline[Close Date], "<" & EDATE(A11,1), Pipeline[Stage], "Closed Won" ) -> 0 | E11: Total Pipeline ARR | F11: =SUM(F5:F10) -> 3543000 | G11: =SUM(G5:G10) -> 1
A12: 45778 | B12: =COUNTIFS( Pipeline[Opportunity Create Date], ">=" & A12, Pipeline[Opportunity Create Date], "<" & EDATE(A12,1) ) -> 19 | C12: =SUMIFS( Pipeline[Annual Recurring Revenue (ARR)], Pipeline[Close Date], ">=" & A12, Pipeline[Close Date], "<" & EDATE(A12,1), Pipeline[Stage], "Closed Won" ) -> 60000
A13: 45809 | B13: =COUNTIFS( Pipeline[Opportunity Create Date], ">=" & A13, Pipeline[Opportunity Create Date], "<" & EDATE(A13,1) ) -> 9 | C13: =SUMIFS( Pipeline[Annual Recurring Revenue (ARR)], Pipeline[Close Date], ">=" & A13, Pipeline[Close Date], "<" & EDATE(A13,1), Pipeline[Stage], "Closed Won" ) -> 555000
A14: 45839 | B14: =COUNTIFS( Pipeline[Opportunity Create Date], ">=" & A14, Pipeline[Opportunity Create Date], "<" & EDATE(A14,1) ) -> 2 | C14: =SUMIFS( Pipeline[Annual Recurring Revenue (ARR)], Pipeline[Close Date], ">=" & A14, Pipeline[Close Date], "<" & EDATE(A14,1), Pipeline[Stage], "Closed Won" ) -> 256000
A15: 45870 | B15: =COUNTIFS( Pipeline[Opportunity Create Date], ">=" & A15, Pipeline[Opportunity Create Date], "<" & EDATE(A15,1) ) -> 1 | C15: =SUMIFS( Pipeline[Annual Recurring Revenue (ARR)], Pipeline[Close Date], ">=" & A15, Pipeline[Close Date], "<" & EDATE(A15,1), Pipeline[Stage], "Closed Won" ) -> 0
A17: Average $ ARR Opp Value | E17: Pipeline Hygiene
A18: All Closed deals | B18: =AVERAGEIF(Data!L:L,"Closed",Data!B:B) -> 57857.143
A19: Closed won deals | B19: =AVERAGEIF(Data!G:G,"Closed won",Data!B:B) -> 62214.286 | E19: # of Total Deals in Pipeline (Open) | F19: =COUNTIF( Pipeline[General Stage], "Open" ) -> 28
A20: Closed lost deals | B20: =AVERAGEIF(Data!G:G,"Closed Lost",Data!B:B) -> 49142.857 | E20: # of Past Due Deals | F20: =COUNTIF( Pipeline[Overdue], "Overdue" ) -> 12
A21: Open Opps | B21: =AVERAGEIF(Data!L:L,"Open",Data!B:B) -> 126535.71 | E21: % Past Due | F21: =F20/F19 -> 0.42857143
A22: Average All Opps (closed and Open) | B22: =AVERAGE(Data!B:B) -> 97102.041 | E22: ARR of Past Due Deals | F22: =SUMIFS( Pipeline[Annual Recurring Revenue (ARR)], Pipeline[Overdue], "Overdue" ) -> 1318000 | G22: =F22 -> 1318000
A24: Sales Cycle Average - Closed Won | D24: Plan
A25: Excluding rows with negative days | B25: =AVERAGEIFS(Data!$M:$M, Data!$G:$G, "Closed Won", Data!$M:$M, ">0") -> 54.846154 | C25: =IF(B25<'Plan '!B16,1,0) -> 1 | D25: ='Plan '!B16 -> 60
A26: If not excluding errors | B26: =IFERROR(AVERAGEIF(Data!$G:$G,"Closed Won",Data!$M:$M),"") -> 49.142857
A28: Win Rate - General | B28: # | C28: % | E28: Plan
A29: Closed Won Deals | B29: =COUNTIF(Data!G:G,"Closed Won") -> 14 | C29: =B29/$B$31 -> 0.66666667 | D29: =IF(C29>'Plan '!B14,1,0) -> 1 | E29: ='Plan '!B14 -> 0.65
A30: Closed Lost Deals | B30: =COUNTIF(Data!G:G,"Closed Lost") -> 7 | C30: =B30/$B$31 -> 0.33333333
B31: =SUM(B29:B30) -> 21 | C31: =SUM(C29:C30) -> 1
A33: Product Line Mix | B33: Closed Deals | C33: % Mix | D33: Closed Won Deals | E33: % Mix | F33: Current Open Deals | G33: % Mix
A34: {=_xlfn._xlws.SORT(_xlfn.UNIQUE(Pipeline[Product Line]))} -> Services | B34: {=COUNTIFS(Pipeline[Product Line],_xlfn.ANCHORARRAY( A34), Pipeline[General Stage], "Closed")} -> 9 | C34: {=_xlfn.ANCHORARRAY(B34)/$B$36} -> 0.42857143 | D34: {=COUNTIFS(Pipeline[Product Line],_xlfn.ANCHORARRAY( A34), Pipeline[Stage], "Closed Won")} -> 7 | E34: {=_xlfn.ANCHORARRAY(D34)/$D$36} -> 0.5 | F34: {=COUNTIFS(Pipeline[Product Line],_xlfn.ANCHORARRAY( A34), Pipeline[General Stage], "Open")} -> 5 | G34: {=_xlfn.ANCHORARRAY(F34)/$F$36} -> 0.17857143
A35: Software | B35: 12 | C35: 0.57142857 | D35: 7 | E35: 0.5 | F35: 23 | G35: 0.82142857
B36: =SUM(_xlfn.ANCHORARRAY(B34)) -> 21 | C36: =SUM(_xlfn.ANCHORARRAY(C34)) -> 1 | D36: =SUM(_xlfn.ANCHORARRAY(D34)) -> 14 | E36: =SUM(_xlfn.ANCHORARRAY(E34)) -> 1 | F36: =SUM(_xlfn.ANCHORARRAY(F34)) -> 28 | G36: =SUM(_xlfn.ANCHORARRAY(G34)) -> 1
A38: Metrics by Sales Rep
B40: Closed Opportunities
A41: Sales Rep | B41: # Total Closed deals per rep | C41: # Total Closed Won deals per rep | D41: Win Rate | E41: Average Closed Won $ ARR | F41: Average Sales Cycle Days | G41: Current open ARR | H41: # Current Opp in Pipeline | I41: Current Average $ ARR | J41: Past Due Deals | K41: Past Due $ARR | L41: Average Days since Opp start date
A42: {=_xlfn._xlws.SORT(_xlfn.UNIQUE(Pipeline[Sales Rep]))} -> Bob Johnson | B42: {=COUNTIFS(Pipeline[Sales Rep],_xlfn.ANCHORARRAY( A42), Pipeline[General Stage], "Closed")} -> 8 | C42: {=COUNTIFS(Pipeline[Sales Rep],_xlfn.ANCHORARRAY( A42), Pipeline[Stage], "Closed Won")} -> 5 | D42: {=_xlfn.ANCHORARRAY(C42)/_xlfn.ANCHORARRAY(B42)} -> 0.625 | E42: {=AVERAGEIFS( Pipeline[Annual Recurring Revenue (ARR)], Pipeline[Sales Rep],_xlfn.ANCHORARRAY( A42), Pipeline[Stage], "Closed Won" )} -> 54000 | F42: {=AVERAGEIFS( Pipeline[Sales Close Days], Pipeline[Sales Rep],_xlfn.ANCHORARRAY( A42), Pipeline[Stage], "Closed Won" )} -> 40.8 | G42: {=SUMIFS( Pipeline[Annual Recurring Revenue (ARR)], Pipeline[Sales Rep],_xlfn.ANCHORARRAY( A42), Pipeline[General Stage], "Open" )} -> 1010000 | H42: {=COUNTIFS( Pipeline[Sales Rep],_xlfn.ANCHORARRAY( A42), Pipeline[General Stage], "Open" )} -> 8 | I42: {=AVERAGEIFS( Pipeline[Annual Recurring Revenue (ARR)], Pipeline[Sales Rep],_xlfn.ANCHORARRAY( A42), Pipeline[General Stage], "Open" )} -> 126250 | J42: {=COUNTIFS( Pipeline[Sales Rep],_xlfn.ANCHORARRAY( A42), Pipeline[Overdue], "Overdue" )} -> 4 | K42: {=SUMIFS( Pipeline[Annual Recurring Revenue (ARR)], Pipeline[Sales Rep],_xlfn.ANCHORARRAY( A42), Pipeline[Overdue], "Overdue" )} -> 425000 | L42: {=AVERAGEIFS(Pipeline[Days past since Opp creation], Pipeline[Sales Rep],_xlfn.ANCHORARRAY( A42))} -> 114.4375
A43: Charlie Brown | B43: 5 | C43: 3 | D43: 0.6 | E43: 63666.667 | F43: 46.333333 | G43: 1510000 | H43: 11 | I43: 137272.73 | J43: 5 | K43: 625000 | L43: 109.0625
A44: Lucy Smith | B44: 8 | C44: 6 | D44: 0.75 | E44: 68333.333 | F44: 57.5 | G44: 1023000 | H44: 9 | I44: 113666.67 | J44: 3 | K44: 268000 | L44: 112.58824
J46: =SUM(J42:J45) -> 12 | K46: =SUM(K42:K45) -> 1318000 | L46: =IF(K46<>$F$22,"⚠ Rows with blank spaces cause inaccuracy in data","")
A48: Metrics by Region
...

Sheet Plan 
A1: Plan - Revenue | E1: Plan Assumptions and Allocation (Sep–Nov)
A3: Period | E3: For the plan, management set a quarterly goal of approximately $1.2M, distributed across Sep–Nov with 35–40% weighted to September and October to reflect stronger early-quarter buying behavior, and 25% allocated to November given holiday seasonality and fewer selling days. A conservative approach was taken in light of market tariff uncertainty and the transition to a new government administration, both of which were expected to influence customer purchasing decisions.
A4: Year | B4: 2025
A5: Month | B5: Sep - Nov
A7: Total ARR | B7: 1215000
A9: Phasing - Seasonality
A10: Sep | B10: 0.35 | C10: =$B$7*B10 -> 425250
A11: Oct | B11: 0.4 | C11: =$B$7*B11 -> 486000
A12: Nov | B12: 0.25 | C12: =$B$7*B12 -> 303750
A14: Win Rate | B14: 0.65
A16: Average Sales Cycle Days | B16: 60

Sheet Data
A1: Account Name | B1: Annual Recurring Revenue (ARR) | C1: Opportunity Create Date | D1: Close Date | E1: Sales Rep | F1: Lead Source | G1: Stage | H1: Probability | I1: Product Line | J1: Region | K1: Customer Segment | L1: General Stage | M1: Sales Close Days | N1: S1 ARR * SF Probability | O1: 1st month of Revenue (SF) | P1: Overdue | Q1: Rev Date according to Sales Stage | R1: Phasing Month Forecast | S1: Days past since Opp creation
A2: Nexus Dynamics | B2: 60000 | C2: 45762 | D2: 45805 | E2: Charlie Brown | F2: Webinar | G2: Closed Won | H2: 1 | I2: Software | J2: North America | K2: SMB | L2: =IF(OR(G2="Closed Won", G2="Closed Lost"), "Closed", "Open") -> Closed | M2: =_xlfn.DAYS(D2,C2) -> 43 | N2: =IF(L2="Open",B2*H2,0) -> 0 | O2: =EOMONTH(D2,0)+1 -> 45809 | P2: =IF(Pipeline[[#This Row],[General Stage]]="Closed", "Closed", IF(O2<'Forecast Sep-Nov 2025'!$J$6,"Overdue","Current") ) -> Closed | Q2: =IF(L2="Closed", EDATE(D2,1), IF( G2="Negotiation/Review", 'Forecast Sep-Nov 2025'!$J$6, IF( G2="Value Proposition", EDATE('Forecast Sep-Nov 2025'!$J$6,1), EDATE('Forecast Sep-Nov 2025'!$J$6,2))) ) -> 45836 | R2: =IF(P2="Overdue",Q2,O2) -> 45809 | S2: =_xlfn.DAYS('Forecast Sep-Nov 2025'!$J$6,Pipeline[[#This Row],[Opportunity Create Date]]) -> 139
A3: InnovateX Ltd. | B3: 45000 | C3: 45757 | D3: 45809 | E3: Lucy Smith | F3: Inbound Marketing | G3: Closed Lost | H3: 0 | I3: Services | J3: APAC | K3: SMB | L3: =IF(OR(G3="Closed Won", G3="Closed Lost"), "Closed", "Open") -> Closed | M3: =_xlfn.DAYS(D3,C3) -> 52 | N3: =IF(L3="Open",B3*H3,0) -> 0 | O3: =EOMONTH(D3,0)+1 -> 45839 | P3: =IF(Pipeline[[#This Row],[General Stage]]="Closed", "Closed", IF(O3<'Forecast Sep-Nov 2025'!$J$6,"Overdue","Current") ) -> Closed | Q3: =IF(L3="Closed", EDATE(D3,1), IF( G3="Negotiation/Review", 'Forecast Sep-Nov 2025'!$J$6, IF( G3="Value Proposition", EDATE('Forecast Sep-Nov 2025'!$J$6,1), EDATE('Forecast Sep-Nov 2025'!$J$6,2))) ) -> 45839 | R3: =IF(P3="Overdue",Q3,O3) -> 45839 | S3: =_xlfn.DAYS('Forecast Sep-Nov 2025'!$J$6,Pipeline[[#This Row],[Opportunity Create Date]]) -> 144
A4: Apex Global | B4: 165000 | C4: 45887 | D4: 45803 | E4: Lucy Smith | F4: Referral | G4: Needs Analysis | H4: 0.4 | I4: Software | L4: =IF(OR(G4="Closed Won", G4="Closed Lost"), "Closed", "Open") -> Open | M4: =_xlfn.DAYS(D4,C4) -> -84 | N4: =IF(L4="Open",B4*H4,0) -> 66000 | O4: =EOMONTH(D4,0)+1 -> 45809 | P4: =IF(Pipeline[[#This Row],[General Stage]]="Closed", "Closed", IF(O4<'Forecast Sep-Nov 2025'!$J$6,"Overdue","Current") ) -> Overdue | Q4: =IF(L4="Closed", EDATE(D4,1), IF( G4="Negotiation/Review", 'Forecast Sep-Nov 2025'!$J$6, IF( G4="Value Proposition", EDATE('Forecast Sep-Nov 2025'!$J$6,1), EDATE('Forecast Sep-Nov 2025'!$J$6,2))) ) -> 45962 | R4: =IF(P4="Overdue",Q4,O4) -> 45962 | S4: =_xlfn.DAYS('Forecast Sep-Nov 2025'!$J$6,Pipeline[[#This Row],[Opportunity Create Date]]) -> 14
A5: Innovision Tech | B5: 42000 | C5: 45758 | D5: 45811 | E5: Lucy Smith | F5: Webinar | G5: Closed Won | H5: 1 | I5: Services | J5: North America | K5: SMB | L5: =IF(OR(G5="Closed Won", G5="Closed Lost"), "Closed", "Open") -> Closed | M5: =_xlfn.DAYS(D5,C5) -> 53 | N5: =IF(L5="Open",B5*H5,0) -> 0 | O5: =EOMONTH(D5,0)+1 -> 45839 | P5: =IF(Pipeline[[#This Row],[General Stage]]="Closed", "Closed", IF(O5<'Forecast Sep-Nov 2025'!$J$6,"Overdue","Current") ) -> Closed | Q5: =IF(L5="Closed", EDATE(D5,1), IF( G5="Negotiation/Review", 'Forecast Sep-Nov 2025'!$J$6, IF( G5="Value Proposition", EDATE('Forecast Sep-Nov 2025'!$J$6,1), EDATE('Forecast Sep-Nov 2025'!$J$6,2))) ) -> 45841 | R5: =IF(P5="Overdue",Q5,O5) -> 45839 | S5: =_xlfn.DAYS('Forecast Sep-Nov 2025'!$J$6,Pipeline[[#This Row],[Opportunity Create Date]]) -> 143
A6: Elite Corp. | B6: 180000 | C6: 45839 | D6: 45769 | E6: Charlie Brown | F6: Referral | G6: Needs Analysis | H6: 0.4 | I6: Software | J6: North America | K6: Enterprise | L6: =IF(OR(G6="Closed Won", G6="Closed Lost"), "Closed", "Open") -> Open | M6: =_xlfn.DAYS(D6,C6) -> -70 | N6: =IF(L6="Open",B6*H6,0) -> 72000 | O6: =EOMONTH(D6,0)+1 -> 45778 | P6: =IF(Pipeline[[#This Row],[General Stage]]="Closed", "Closed", IF(O6<'Forecast Sep-Nov 2025'!$J$6,"Overdue","Current") ) -> Overdue | Q6: =IF(L6="Closed", EDATE(D6,1), IF( G6="Negotiation/Review", 'Forecast Sep-Nov 2025'!$J$6, IF( G6="Value Proposition", EDATE('Forecast Sep-Nov 2025'!$J$6,1), EDATE('Forecast Sep-Nov 2025'!$J$6,2))) ) -> 45962 | R6: =IF(P6="Overdue",Q6,O6) -> 45962 | S6: =_xlfn.DAYS('Forecast Sep-Nov 2025'!$J$6,Pipeline[[#This Row],[Opportunity Create Date]]) -> 62
A7: Synergy Systems | B7: 55000 | C7: 45772 | D7: 45813 | E7: Lucy Smith | F7: Webinar | G7: Closed Lost | H7: 0 | I7: Software | J7: EMEA | K7: Mid-Market | L7: =IF(OR(G7="Closed Won", G7="Closed Lost"), "Closed", "Open") -> Closed | M7: =_xlfn.DAYS(D7,C7) -> 41 | N7: =IF(L7="Open",B7*H7,0) -> 0 | O7: =EOMONTH(D7,0)+1 -> 45839 | P7: =IF(Pipeline[[#This Row],[General Stage]]="Closed", "Closed", IF(O7<'Forecast Sep-Nov 2025'!$J$6,"Overdue","Current") ) -> Closed | Q7: =IF(L7="Closed", EDATE(D7,1), IF( G7="Negotiation/Review", 'Forecast Sep-Nov 2025'!$J$6, IF( G7="Value Proposition", EDATE('Forecast Sep-Nov 2025'!$J$6,1), EDATE('Forecast Sep-Nov 2025'!$J$6,2))) ) -> 45843 | R7: =IF(P7="Overdue",Q7,O7) -> 45839 | S7: =_xlfn.DAYS('Forecast Sep-Nov 2025'!$J$6,Pipeline[[#This Row],[Opportunity Create Date]]) -> 129
A8: Catalyst Innovations | B8: 70000 | C8: 45820 | D8: 45856 | E8: Lucy Smith | F8: Referral | G8: Value Proposition | H8: 0.6 | I8: Software | J8: EMEA | K8: Mid-Market | L8: =IF(OR(G8="Closed Won", G8="Closed Lost"), "Closed", "Open") -> Open | M8: =_xlfn.DAYS(D8,C8) -> 36 | N8: =IF(L8="Open",B8*H8,0) -> 42000 | O8: =EOMONTH(D8,0)+1 -> 45870 | P8: =IF(Pipeline[[#This Row],[General Stage]]="Closed", "Closed", IF(O8<'Forecast Sep-Nov 2025'!$J$6,"Overdue","Current") ) -> Overdue | Q8: =IF(L8="Closed", EDATE(D8,1), IF( G8="Negotiation/Review", 'Forecast Sep-Nov 2025'!$J$6, IF( G8="Value Proposition", EDATE('Forecast Sep-Nov 2025'!$J$6,1), EDATE('Forecast Sep-Nov 2025'!$J$6,2))) ) -> 45931 | R8: =IF(P8="Overdue",Q8,O8) -> 45931 | S8: =_xlfn.DAYS('Forecast Sep-Nov 2025'!$J$6,Pipeline[[#This Row],[Opportunity Create Date]]) -> 81
A9: Zenith Innovations | B9: 58000 | C9: 45771 | D9: 45816 | E9: Charlie Brown | F9: Webinar | G9: Closed Lost | H9: 0 | I9: Software | J9: EMEA | K9: Mid-Market | L9: =IF(OR(G9="Closed Won", G9="Closed Lost"), "Closed", "Open") -> Closed | M9: =_xlfn.DAYS(D9,C9) -> 45 | N9: =IF(L9="Open",B9*H9,0) -> 0 | O9: =EOMONTH(D9,0)+1 -> 45839 | P9: =IF(Pipeline[[#This Row],[General Stage]]="Closed", "Closed", IF(O9<'Forecast Sep-Nov 2025'!$J$6,"Overdue","Current") ) -> Closed | Q9: =IF(L9="Closed", EDATE(D9,1), IF( G9="Negotiation/Review", 'Forecast Sep-Nov 2025'!$J$6, IF( G9="Value Proposition", EDATE('Forecast Sep-Nov 2025'!$J$6,1), EDATE('Forecast Sep-Nov 2025'!$J$6,2))) ) -> 45846 | R9: =IF(P9="Overdue",Q9,O9) -> 45839 | S9: =_xlfn.DAYS('Forecast Sep-Nov 2025'!$J$6,Pipeline[[#This Row],[Opportunity Create Date]]) -> 130
A10: Global Connect | B10: 95000 | C10: 45797 | D10: 45843 | E10: Charlie Brown | F10: Partner | G10: Value Proposition | H10: 0.6 | I10: Software | J10: EMEA | K10: Mid-Market | L10: =IF(OR(G10="Closed Won", G10="Closed Lost"), "Closed", "Open") -> Open | M10: =_xlfn.DAYS(D10,C10) -> 46 | N10: =IF(L10="Open",B10*H10,0) -> 57000 | O10: =EOMONTH(D10,0)+1 -> 45870 | P10: =IF(Pipeline[[#This Row],[General Stage]]="Closed", "Closed", IF(O10<'Forecast Sep-Nov 2025'!$J$6,"Overdue","Current") ) -> Overdue | Q10: =IF(L10="Closed", EDATE(D10,1), IF( G10="Negotiation/Review", 'Forecast Sep-Nov 2025'!$J$6, IF( G10="Value Proposition", EDATE('Forecast Sep-Nov 2025'!$J$6,1), EDATE('Forecast Sep-Nov 2025'!$J$6,2))) ) -> 45931 | R10: =IF(P10="Overdue",Q10,O10) -> 45931 | S10: =_xlfn.DAYS('Forecast Sep-Nov 2025'!$J$6,Pipeline[[#This Row],[Opportunity Create Date]]) -> 104
A11: Quantum Enterprises | B11: 30000 | C11: 45767 | D11: 45818 | E11: Bob Johnson | F11: Inbound Marketing | G11: Closed Won | H11: 1 | I11: Services | J11: APAC | K11: SMB | L11: =IF(OR(G11="Closed Won", G11="Closed Lost"), "Closed", "Open") -> Closed | M11: =_xlfn.DAYS(D11,C11) -> 51 | N11: =IF(L11="Open",B11*H11,0) -> 0 | O11: =EOMONTH(D11,0)+1 -> 45839 | P11: =IF(Pipeline[[#This Row],[General Stage]]="Closed", "Closed", IF(O11<'Forecast Sep-Nov 2025'!$J$6,"Overdue","Current") ) -> Closed | Q11: =IF(L11="Closed", EDATE(D11,1), IF( G11="Negotiation/Review", 'Forecast Sep-Nov 2025'!$J$6, IF( G11="Value Proposition", EDATE('Forecast Sep-Nov 2025'!$J$6,1), EDATE('Forecast Sep-Nov 2025'!$J$6,2))) ) -> 45848 | R11: =IF(P11="Overdue",Q11,O11) -> 45839 | S11: =_xlfn.DAYS('Forecast Sep-Nov 2025'!$J$6,Pipeline[[#This Row],[Opportunity Create Date]]) -> 134
A12: Global Reach Inc. | B12: 85000 | C12: 45828 | D12: 45874 | E12: Lucy Smith | F12: Inbound Marketing | G12: Qualification | H12: 0.2 | I12: Software | J12: North America | K12: Mid-Market | L12: =IF(OR(G12="Closed Won", G12="Closed Lost"), "Closed", "Open") -> Open | M12: =_xlfn.DAYS(D12,C12) -> 46 | N12: =IF(L12="Open",B12*H12,0) -> 17000 | O12: =EOMONTH(D12,0)+1 -> 45901 | P12: =IF(Pipeline[[#This Row],[General Stage]]="Closed", "Closed", IF(O12<'Forecast Sep-Nov 2025'!$J$6,"Overdue","Current") ) -> Current | Q12: =IF(L12="Closed", EDATE(D12,1), IF( G12="Negotiation/Review", 'Forecast Sep-Nov 2025'!$J$6, IF( G12="Value Proposition", EDATE('Forecast Sep-Nov 2025'!$J$6,1), EDATE('Forecast Sep-Nov 2025'!$J$6,2))) ) -> 45962 | R12: =IF(P12="Overdue",Q12,O12) -> 45901 | S12: =_xlfn.DAYS('Forecast Sep-Nov 2025'!$J$6,Pipeline[[#This Row],[Opportunity Create Date]]) -> 73
A13: BrightSpot Inc. | B13: 98000 | C13: 45798 | D13: 45845 | E13: Bob Johnson | F13: Partner | G13: Negotiation/Review | H13: 0.8 | I13: Software | J13: EMEA | K13: Mid-Market | L13: =IF(OR(G13="Closed Won", G13="Closed Lost"), "Closed", "Open") -> Open | M13: =_xlfn.DAYS(D13,C13) -> 47 | N13: =IF(L13="Open",B13*H13,0) -> 78400 | O13: =EOMONTH(D13,0)+1 -> 45870 | P13: =IF(Pipeline[[#This Row],[General Stage]]="Closed", "Closed", IF(O13<'Forecast Sep-Nov 2025'!$J$6,"Overdue","Current") ) -> Overdue | Q13: =IF(L13="Closed", EDATE(D13,1), IF( G13="Negotiation/Review", 'Forecast Sep-Nov 2025'!$J$6, IF( G13="Value Proposition", EDATE('Forecast Sep-Nov 2025'!$J$6,1), EDATE('Forecast Sep-Nov 2025'!$J$6,2))) ) -> 45901 | R13: =IF(P13="Overdue",Q13,O13) -> 45901 | S13: =_xlfn.DAYS('Forecast Sep-Nov 2025'!$J$6,Pipeline[[#This Row],[Opportunity Create Date]]) -> 103
A14: Summit Corp. | B14: 78000 | C14: 45763 | D14: 45820 | E14: Charlie Brown | F14: Outbound SDR | G14: Closed Won | H14: 1 | I14: Software | J14: North America | K14: Mid-Market | L14: =IF(OR(G14="Closed Won", G14="Closed Lost"), "Closed", "Open") -> Closed | M14: =_xlfn.DAYS(D14,C14) -> 57 | N14: =IF(L14="Open",B14*H14,0) -> 0 | O14: =EOMONTH(D14,0)+1 -> 45839 | P14: =IF(Pipeline[[#This Row],[General Stage]]="Closed", "Closed", IF(O14<'Forecast Sep-Nov 2025'!$J$6,"Overdue","Current") ) -> Closed | Q14: =IF(L14="Closed", EDATE(D14,1), IF( G14="Negotiation/Review", 'Forecast Sep-Nov 2025'!$J$6, IF( G14="Value Proposition", EDATE('Forecast Sep-Nov 2025'!$J$6,1), EDATE('Forecast Sep-Nov 2025'!$J$6,2))) ) -> 45850 | R14: =IF(P14="Overdue",Q14,O14) -> 45839 | S14: =_xlfn.DAYS('Forecast Sep-Nov 2025'!$J$6,Pipeline[[#This Row],[Opportunity Create Date]]) -> 138
A15: Everest Corp. | B15: 110000 | C15: 45813 | D15: 45870 | E15: Lucy Smith | F15: Partner | G15: Qualification | H15: 0.2 | I15: Software | J15: EMEA | K15: Enterprise | L15: =IF(OR(G15="Closed Won", G15="Closed Lost"), "Closed", "Open") -> Open | M15: =_xlfn.DAYS(D15,C15) -> 57 | N15: =IF(L15="Open",B15*H15,0) -> 22000 | O15: =EOMONTH(D15,0)+1 -> 45901 | P15: =IF(Pipeline[[#This Row],[General Stage]]="Closed", "Closed", IF(O15<'Forecast Sep-Nov 2025'!$J$6,"Overdue","Current") ) -> Current | Q15: =IF(L15="Closed", EDATE(D15,1), IF( G15="Negotiation/Review", 'Forecast Sep-Nov 2025'!$J$6, IF( G15="Value Proposition", EDATE('Forecast Sep-Nov 2025'!$J$6,1), EDATE('Forecast Sep-Nov 2025'!$J$6,2))) ) -> 45962 | R15: =IF(P15="Overdue",Q15,O15) -> 45901 | S15: =_xlfn.DAYS('Forecast Sep-Nov 2025'!$J$6,Pipeline[[#This Row],[Opportunity Create Date]]) -> 88
A16: Horizon Innovations | B16: 80000 | C16: 45780 | D16: 45839 | E16: Charlie Brown | F16: Partner | G16: Negotiation/Review | H16: 0.8 | I16: Services | J16: APAC | K16: Enterprise | L16: =IF(OR(G16="Closed Won", G16="Closed Lost"), "Closed", "Open") -> Open | M16: =_xlfn.DAYS(D16,C16) -> 59 | N16: =IF(L16="Open",B16*H16,0) -> 64000 | O16: =EOMONTH(D16,0)+1 -> 45870 | P16: =IF(Pipeline[[#This Row],[General Stage]]="Closed", "Closed", IF(O16<'Forecast Sep-Nov 2025'!$J$6,"Overdue","Current") ) -> Overdue | Q16: =IF(L16="Closed", EDATE(D16,1), IF( G16="Negotiation/Review", 'Forecast Sep-Nov 2025'!$J$6, IF( G16="Value Proposition", EDATE('Forecast Sep-Nov 2025'!$J$6,1), EDATE('Forecast Sep-Nov 2025'!$J$6,2))) ) -> 45901 | R16: =IF(P16="Overdue",Q16,O16) -> 45901 | S16: =_xlfn.DAYS('Forecast Sep-Nov 2025'!$J$6,Pipeline[[#This Row],[Opportunity Create Date]]) -> 121
... A50: Future Systems Corp. | B50: 200000 | C50: 45749 | D50: 45868 | E50: Charlie Brown | F50: Outbound SDR | G50: Negotiation/Review | H50: 0.8 | I50: Software | J50: EMEA | K50: Enterprise | L50: =IF(OR(G50="Closed Won", G50="Closed Lost"), "Closed", "Open") -> Open | M50: =_xlfn.DAYS(D50,C50) -> 119 | N50: =IF(L50="Open",B50*H50,0) -> 160000 | O50: =EOMONTH(D50,0)+1 -> 45870 | P50: =IF(Pipeline[[#This Row],[General Stage]]="Closed", "Closed", IF(O50<'Forecast Sep-Nov 2025'!$J$6,"Overdue","Current") ) -> Overdue | Q50: =IF(L50="Closed", EDATE(D50,1), IF( G50="Negotiation/Review", 'Forecast Sep-Nov 2025'!$J$6, IF( G50="Value Proposition", EDATE('Forecast Sep-Nov 2025'!$J$6,1), EDATE('Forecast Sep-Nov 2025'!$J$6,2))) ) -> 45901 | R50: =IF(P50="Overdue",Q50,O50) -> 45901 | S50: =_xlfn.DAYS('Forecast Sep-Nov 2025'!$J$6,Pipeline[[#This Row],[Opportunity Create Date]]) -> 152

Sheet Assignment Approach
B3: Case Approach & Notes
B5: Process summary
B6: 1. Data Source Received
B7: Salesforce pipeline download provided as the starting dataset.
B8: 2. Addition of helper columns
B9: Added helper columns (top row in green) to simplify calculations
B10: Ensures the model refreshes automatically when new data is added or replaced, minimizing manual adjustments.
B11: 3. Metrics calculations
B12: Most metrics calculated with spill formulas for automation (vs. pivot tables that require manual refresh).
B13: Designed for scalability when new data is pulled.
B14: 4. Inclusion of an Automated Dashboard
B15: Created a dashboard linked to metrics, focused on the Take-Home Assignment questions.
... B23: Glossary for helper columns context
B24: Column | C24: Description
B25: General Stage | C25: Categorizes opportunities as Open or Closed deals.
B26: Sales Close Days | C26: Number of days between Opportunity Create Date and Salesforce Close Date.
B27: S1 ARR * SF Probability | C27: Calculates ARR multiplied by the Salesforce probability % for that opportunity.
B28: 1st month of Revenue (SF) | C28: Assigns the first revenue month as the immediate month following the Salesforce Close Date.
B29: Overdue | C29: Flags opportunities with a Close Date earlier than the current month (Sep 2025) as Overdue; opportunities with future close dates are Current.
B30: Rev Date according to Sales Stage | C30: Uses Close Date and adjusts it based on the sales stage to determine if revenue is expected in Sep, Oct, or Nov. Ensures overdue opportunities are rephased according to stage progression.
B31: Phasing Month Forecast | C31: Overdue opportunities → reassigned to Sep, Oct, or Nov based on sales stage (e.g., Negotiation → Sep, Value Proposition → Oct, Prospecting/Qualification → Nov). Current /Not overdue opportunities → keep their original Salesforce Close Date (no stage adjustment applied).
B32: Days past since Opp creation | C32: Days between Opportunity Create Date and Sep 1, 2025.
